File: Experiment/Experiment/Sample 1 Data/Sample1_280MPa_550C_200h.csv
Date/Clock time,45685.4,,,,,,,,,
Tester,Mehdi,,,,,,,,,
Specimen designation,316H-elg_280MPa_550C_01,,,,,,,,,
Diameter,6.059,mm,,,,,,,,
Material,316H-elg,,,,,,,,,
Load cell,100kN,,,,,,,,,
Extensometer,Epsilon 3549 SN102121 GL25mm,,,,,,,,,
"Gauge length, standard travel",25,mm,,,,,,,,
Test standard,ASTM E136,,,,,,,,,
Machine data,ZwickRoell Kappa100 SS-CF,,,,,,,,,
Time,Test time,Standard travel,Standard force,Temperature,Temperature 3,,,,,
h,h,%,MPa,°C,°C,,,,,
3.51323,3.51291,0,1.87015,548.812,550.359,,,,,
3.51347,3.51315,-0.000697853,3.69566,548.812,550.349,,,,,
3.51365,3.51333,-0.000480144,5.50813,548.807,550.349,,,,,
3.51383,3.51351,-0.000726114,7.30422,548.818,550.348,,,,,
3.51399,3.51367,-0.000743322,9.13026,548.818,550.357,,,,,
3.51412,3.5138,-0.000262162,11.0217,548.809,550.357,,,,,
3.51423,3.51391,0.000487606,12.8906,548.809,550.357,,,,,
3.51433,3.51401,0.00114806,14.6846,548.809,550.365,,,,,
3.51443,3.51411,0.00282858,16.6332,548.809,550.365,,,,,
3.51452,3.5142,0.00428423,18.5149,548.809,550.374,,,,,
3.5146,3.51428,0.00573208,20.3481,548.814,550.374,,,,,
3.51468,3.51436,0.00727225,22.1946,548.814,550.374,,,,,
3.51477,3.51445,0.00869296,24.0465,548.814,550.374,,,,,
3.51485,3.51453,0.00984494,25.9376,548.814,550.37,,,,,
3.51493,3.51461,0.0107014,27.8401,548.823,550.37,,,,,
3.51502,3.5147,0.0117546,29.7327,548.823,550.37,,,,,
3.5151,3.51478,0.0131329,31.6402,548.823,550.368,,,,,
3.51518,3.51486,0.0141923,33.5417,548.832,550.368,,,,,
3.51527,3.51495,0.0149508,35.4597,548.832,550.368,,,,,
3.51535,3.51503,0.0160747,37.4091,548.832,550.368,,,,,
3.51543,3.51511,0.016754,39.3562,548.829,550.365,,,,,
3.51552,3.5152,0.0171818,41.2643,548.829,550.365,,,,,
3.5156,3.51528,0.0177224,43.1917,548.829,550.365,,,,,
3.51568,3.51536,0.0182938,45.1175,548.829,550.365,,,,,
3.51577,3.51545,0.0192154,47.0492,548.836,550.365,,,,,
3.51585,3.51553,0.0207281,48.9917,548.836,550.365,,,,,
3.51593,3.51561,0.0224042,50.8779,548.836,550.363,,,,,
3.51602,3.5157,0.023943,52.7851,548.835,550.363,,,,,
3.5161,3.51578,0.0255097,54.6895,548.835,550.363,,,,,
3.51618,3.51586,0.0267683,56.6063,548.835,550.363,,,,,
3.51627,3.51595,0.0280527,58.5099,548.835,550.37,,,,,
3.51635,3.51603,0.0293175,60.3987,548.823,550.37,,,,,
3.51643,3.51611,0.0303076,62.2516,548.823,550.37,,,,,
3.51652,3.5162,0.0312743,64.1178,548.823,550.372,,,,,
3.5166,3.51628,0.0326186,66.0132,548.827,550.372,,,,,
3.51668,3.51636,0.0339732,67.873,548.827,550.372,,,,,
3.51677,3.51645,0.0354798,69.723,548.827,550.372,,,,,
3.51685,3.51653,0.0370472,71.6001,548.83,550.365,,,,,
3.51694,3.51662,0.0383392,73.4294,548.83,550.365,,,,,
3.51702,3.5167,0.0395054,75.2659,548.83,550.365,,,,,
3.5171,3.51678,0.0405802,77.1047,548.83,550.368,,,,,
3.51719,3.51687,0.0421511,78.989,548.826,550.368,,,,,
3.51727,3.51696,0.0435709,80.7791,548.826,550.368,,,,,
3.51736,3.51704,0.0452708,82.5971,548.826,550.367,,,,,
3.51744,3.51713,0.047131,84.3846,548.83,550.367,,,,,
3.51754,3.51722,0.048748,86.329,548.83,550.367,,,,,
3.51764,3.51732,0.0505652,88.2823,548.83,550.372,,,,,
3.51773,3.51741,0.0525121,90.2285,548.836,550.372,,,,,
3.51783,3.51751,0.0542215,92.1323,548.836,550.372,,,,,
3.51793,3.51761,0.0557342,94.0136,548.836,550.361,,,,,
3.51802,3.51771,0.0566296,95.8042,548.827,550.361,,,,,
3.51812,3.5178,0.0575841,97.5743,548.827,550.361,,,,,
3.51822,3.51791,0.0586334,99.4166,548.827,550.353,,,,,
3.51834,3.51802,0.0599809,101.295,548.83,550.353,,,,,
3.51845,3.51813,0.0618743,103.101,548.83,550.353,,,,,
3.51857,3.51825,0.0652933,104.954,548.82,550.355,,,,,
3.51869,3.51838,0.0686034,106.785,548.82,550.355,,,,,
3.51884,3.51852,0.0726179,108.622,548.812,550.361,,,,,
3.51899,3.51868,0.077499,110.458,548.812,550.361,,,,,
3.51919,3.51887,0.0843099,112.269,548.807,550.369,,,,,
3.51943,3.51911,0.0956778,114.064,548.812,550.356,,,,,
3.51969,3.51937,0.108748,115.827,548.824,550.36,,,,,
3.51995,3.51963,0.118973,117.595,548.824,550.367,,,,,
3.52022,3.5199,0.129716,119.386,548.821,550.367,,,,,
3.5205,3.52018,0.141867,121.166,548.812,550.368,,,,,
3.52077,3.52046,0.154183,122.923,548.81,550.375,,,,,
3.52106,3.52074,0.16752,124.686,548.817,550.368,,,,,
3.52136,3.52104,0.181894,126.446,548.82,550.367,,,,,
3.52167,3.52135,0.195753,128.213,548.822,550.359,,,,,
3.52199,3.52167,0.208549,129.992,548.822,550.366,,,,,
3.52232,3.52201,0.222817,131.781,548.822,550.371,,,,,
3.52267,3.52236,0.238396,133.551,548.823,550.377,,,,,
3.52304,3.52273,0.257695,135.328,548.836,550.366,,,,,
3.52342,3.52311,0.276721,137.091,548.841,550.367,,,,,
3.52382,3.5235,0.296158,138.845,548.826,550.377,,,,,
3.52424,3.52393,0.316413,140.609,548.828,550.375,,,,,
3.52469,3.52437,0.337306,142.374,548.835,550.375,,,,,
3.52515,3.52483,0.357519,144.136,548.822,550.381,,,,,
3.52566,3.52534,0.381476,145.901,548.831,550.375,,,,,
3.52618,3.52586,0.406374,147.645,548.845,550.379,,,,,
3.52675,3.52643,0.434397,149.414,548.841,550.382,,,,,
3.52736,3.52704,0.465374,151.165,548.841,550.397,,,,,
3.528,3.52768,0.498286,152.92,548.866,550.394,,,,,
3.52869,3.52837,0.535254,154.677,548.858,550.402,,,,,
3.52944,3.52912,0.569391,156.427,548.877,550.418,,,,,
3.53022,3.52991,0.608024,158.178,548.871,550.434,,,,,
3.53107,3.53075,0.649288,159.926,548.882,550.439,,,,,
3.53195,3.53163,0.694442,161.676,548.898,550.447,,,,,
3.53292,3.5326,0.744809,163.422,548.902,550.452,,,,,
3.53391,3.53359,0.803454,165.174,548.925,550.48,,,,,
3.53496,3.53464,0.84854,166.925,548.921,550.495,,,,,
3.53596,3.53564,0.903535,168.673,548.94,550.503,,,,,
3.53761,3.53729,1.00498,170.416,548.967,550.522,,,,,
3.53825,3.53793,1.04114,172.168,548.967,550.53,,,,,
3.53912,3.5388,1.05794,173.933,548.977,550.539,,,,,
3.53939,3.53907,1.06087,175.723,548.981,550.556,,,,,
3.53967,3.53936,1.0718,173.936,548.981,550.553,,,,,
3.54097,3.54065,1.14328,174.984,549.013,550.569,,,,,
3.54224,3.54192,1.24527,176.733,549.023,550.577,,,,,
3.54303,3.54271,1.30933,178.483,549.033,550.589,,,,,
3.54384,3.54352,1.34523,180.23,549.042,550.6,,,,,
3.54467,3.54436,1.35373,181.248,549.057,550.609,,,,,
3.54554,3.54522,1.37373,180.147,549.066,550.63,,,,,
3.54666,3.54634,1.45319,181.891,549.068,550.623,,,,,
3.54775,3.54743,1.54255,183.635,549.094,550.644,,,,,
3.54876,3.54844,1.62217,185.38,549.108,550.658,,,,,
3.54993,3.54961,1.66536,186.435,549.111,550.671,,,,,
3.55028,3.54996,1.66747,187.515,549.131,550.669,,,,,
3.55061,3.55029,1.66695,186.42,549.126,550.68,,,,,
3.55174,3.55142,1.68826,187.468,549.136,550.698,,,,,
3.55306,3.55274,1.78944,189.216,549.151,550.711,,,,,
3.55412,3.55381,1.87973,190.964,549.176,550.71,,,,,
3.55581,3.55549,1.99431,192.71,549.193,550.744,,,,,
3.5567,3.55638,2.00273,194.462,549.204,550.742,,,,,
3.55702,3.5567,2.00585,196.246,549.203,550.748,,,,,
3.55721,3.55689,2.00645,194.972,549.203,550.744,,,,,
3.5573,3.55698,2.00585,193.058,549.205,550.744,,,,,
3.55868,3.55836,2.04075,194.8,549.216,550.759,,,,,
3.55992,3.5596,2.13295,196.545,549.231,550.764,,,,,
3.56116,3.56084,2.23673,198.29,549.241,550.762,,,,,
3.56286,3.56254,2.34362,200.045,549.255,550.795,,,,,
3.56363,3.56331,2.35195,201.793,549.255,550.8,,,,,
3.56419,3.56387,2.35261,202.822,549.269,550.801,,,,,
3.56429,3.56397,2.35194,200.905,549.268,550.801,,,,,
3.56571,3.56539,2.37675,201.95,549.263,550.821,,,,,
3.567,3.56668,2.47566,203.694,549.276,550.821,,,,,
3.56858,3.56826,2.60922,205.437,549.293,550.827,,,,,
3.57,3.56968,2.70303,207.191,549.313,550.833,,,,,
3.57139,3.57107,2.72076,208.948,549.307,550.846,,,,,
3.57165,3.57133,2.72279,210.729,549.315,550.854,,,,,
3.57196,3.57164,2.72473,211.78,549.314,550.867,,,,,
3.57201,3.57169,2.7234,209.694,549.314,550.867,,,,,
3.57211,3.57179,2.7225,207.858,549.308,550.867,,,,,
3.57356,3.57324,2.75118,209.604,549.313,550.868,,,,,
3.57504,3.57472,2.86565,211.345,549.323,550.859,,,,,
3.57692,3.57661,3.02519,213.087,549.343,550.874,,,,,
3.57785,3.57753,3.09158,214.829,549.35,550.866,,,,,
3.57903,3.57871,3.11689,216.573,549.359,550.875,,,,,
3.57952,3.57921,3.11873,218.341,549.351,550.875,,,,,
3.57988,3.57956,3.1209,217.835,549.357,550.88,,,,,
3.57996,3.57964,3.12025,215.972,549.357,550.88,,,,,
3.58129,3.58097,3.13074,217.019,549.348,550.88,,,,,
3.58295,3.58263,3.24968,218.762,549.361,550.887,,,,,
3.58475,3.58443,3.40154,220.504,549.365,550.879,,,,,
3.58579,3.58547,3.48899,222.248,549.378,550.884,,,,,
3.58682,3.5865,3.52784,224.002,549.387,550.894,,,,,
3.58759,3.58727,3.53042,223.605,549.379,550.901,,,,,
3.58797,3.58765,3.53105,225.4,549.374,550.894,,,,,
3.58824,3.58792,3.53302,227.171,549.366,550.898,,,,,
3.58859,3.58827,3.53544,227.422,549.37,550.896,,,,,
3.58863,3.58831,3.53439,225.444,549.37,550.896,,,,,
3.58916,3.58884,3.53561,224.257,549.377,550.899,,,,,
3.59102,3.5907,3.60688,225.998,549.374,550.9,,,,,
3.59294,3.59262,3.76983,227.746,549.384,550.885,,,,,
3.59411,3.59379,3.86731,229.49,549.387,550.897,,,,,
3.59521,3.59489,3.94344,231.234,549.375,550.894,,,,,
3.59627,3.59595,3.96725,232.977,549.377,550.896,,,,,
3.59697,3.59665,3.97117,234.73,549.383,550.898,,,,,
3.59754,3.59722,3.97361,235.026,549.389,550.904,,,,,
3.5976,3.59728,3.97241,233.144,549.389,550.904,,,,,
3.59828,3.59796,3.9719,232.741,549.376,550.898,,,,,
3.60077,3.60045,4.09762,234.485,549.381,550.889,,,,,
3.60221,3.60189,4.21904,236.223,549.387,550.892,,,,,
3.60354,3.60322,4.32996,237.962,549.391,550.9,,,,,
3.6047,3.60438,4.40658,239.71,549.391,550.896,,,,,
3.60553,3.60521,4.43043,241.456,549.384,550.892,,,,,
3.60686,3.60654,4.43509,242.508,549.378,550.9,,,,,
3.60708,3.60676,4.43682,244.297,549.384,550.9,,,,,
3.60744,3.60713,4.44006,245.3,549.386,550.901,,,,,
3.60749,3.60717,4.43896,243.155,549.386,550.901,,,,,
3.60754,3.60722,4.43773,241.133,549.383,550.901,,,,,
3.60875,3.60843,4.44118,241.466,549.379,550.894,,,,,
3.6109,3.61058,4.58182,243.211,549.376,550.894,,,,,
3.61229,3.61197,4.69081,244.953,549.397,550.895,,,,,
3.61365,3.61333,4.80227,246.697,549.402,550.899,,,,,
3.61473,3.61441,4.88473,248.446,549.385,550.9,,,,,
3.61622,3.6159,4.92408,250.189,549.389,550.91,,,,,
3.61689,3.61657,4.92571,251.945,549.377,550.904,,,,,
3.61757,3.61725,4.92919,253.706,549.382,550.902,,,,,
3.61769,3.61737,4.92855,251.773,549.382,550.902,,,,,
3.61774,3.61742,4.9277,249.89,549.382,550.904,,,,,
3.61918,3.61886,4.93294,250.219,549.383,550.907,,,,,
3.6212,3.62088,5.06053,251.958,549.383,550.908,,,,,
3.62272,3.62241,5.18747,253.702,549.384,550.912,,,,,
3.62407,3.62376,5.29477,255.448,549.391,550.916,,,,,
3.62517,3.62485,5.3788,257.194,549.382,550.918,,,,,
3.6266,3.62628,5.43269,258.938,549.384,550.918,,,,,
3.62767,3.62735,5.43951,260.688,549.388,550.923,,,,,
3.62826,3.62794,5.44012,261.073,549.383,550.919,,,,,
3.62847,3.62815,5.44079,262.855,549.376,550.921,,,,,
3.62883,3.62851,5.44178,263.144,549.375,550.927,,,,,
3.62887,3.62855,5.44068,261.064,549.375,550.927,,,,,
3.62892,3.6286,5.43953,258.938,549.375,550.922,,,,,
3.62929,3.62898,5.44053,258.571,549.367,550.928,,,,,
3.63153,3.63121,5.50597,260.319,549.364,550.923,,,,,
3.63322,3.6329,5.64616,262.064,549.378,550.912,,,,,
3.63465,3.63433,5.76682,263.81,549.39,550.922,,,,,
3.63584,3.63552,5.86362,265.55,549.386,550.923,,,,,
3.63731,3.63699,5.96407,267.296,549.37,550.937,,,,,
3.63866,3.63834,5.98723,269.041,549.384,550.935,,,,,
3.6393,3.63898,5.98934,270.799,549.376,550.936,,,,,
3.63999,3.63967,5.99308,271.056,549.37,550.94,,,,,
3.64004,3.63972,5.9917,268.984,549.37,550.94,,,,,
3.64036,3.64004,5.99112,267.777,549.372,550.941,,,,,
3.64266,3.64234,6.02753,269.524,549.383,550.951,,,,,
3.64451,3.64419,6.17421,271.267,549.373,550.951,,,,,
3.64596,3.64564,6.29357,273.008,549.395,550.959,,,,,
3.64752,3.6472,6.42217,274.752,549.387,550.966,,,,,
3.64877,3.64846,6.51473,276.496,549.395,550.972,,,,,
3.65014,3.64982,6.5525,278.24,549.384,550.976,,,,,
3.65134,3.65102,6.55635,278.566,549.384,550.975,,,,,
3.65166,3.65134,6.5561,278.909,549.388,550.986,,,,,
3.6853,3.68498,6.56833,280.001,549.264,550.889,,,,,
3.76864,3.76832,6.57483,280.003,549.235,550.727,,,,,
3.85197,3.85165,6.57908,280.001,549.226,550.598,,,,,
3.9353,3.93498,6.58613,279.992,549.246,550.545,,,,,
4.01864,4.01832,6.59014,279.992,549.234,550.567,,,,,
4.10197,4.10165,6.59309,279.997,549.122,550.545,,,,,
4.1853,4.18498,6.59467,280.003,548.918,550.503,,,,,
4.26864,4.26832,6.59718,280.005,549.437,550.29,,,,,
4.35197,4.35165,6.60114,279.998,549.498,550.247,,,,,
4.4353,4.43498,6.59349,280.001,549.439,550.14,,,,,
4.51864,4.51832,6.59394,280,549.468,550.115,,,,,
4.60197,4.60165,6.59633,280,549.506,550.096,,,,,
4.8853,4.88498,6.60554,279.996,549.677,550.073,,,,,
5.30197,5.30165,6.60436,280.003,549.813,549.981,,,,,
5.71864,5.71832,6.61137,280.002,549.998,549.937,,,,,
6.1353,6.13498,6.61099,279.997,550.017,549.83,,,,,
6.55197,6.55165,6.62325,279.99,549.996,549.731,,,,,
6.96864,6.96832,6.62105,279.996,550.047,549.779,,,,,
7.3853,7.38498,6.63198,279.998,549.96,549.716,,,,,
7.80197,7.80165,6.6288,279.999,549.99,549.81,,,,,
8.21864,8.21832,6.6384,279.998,550.033,549.939,,,,,
8.6353,8.63498,6.64067,280.003,549.981,549.914,,,,,
9.05197,9.05165,6.63403,279.997,549.924,549.895,,,,,
9.46864,9.46832,6.64494,279.998,550.014,550.041,,,,,
9.8853,9.88498,6.64985,280,549.911,549.939,,,,,
10.302,10.3016,6.65199,279.994,549.832,549.894,,,,,
10.7186,10.7183,6.65385,280.004,549.923,549.969,,,,,
11.1353,11.135,6.65767,279.994,549.941,549.984,,,,,
11.552,11.5516,6.65604,279.993,549.778,549.797,,,,,
11.9686,11.9683,6.65843,279.985,549.919,549.937,,,,,
12.3853,12.385,6.6614,279.998,549.926,549.92,,,,,
12.802,12.8016,6.66515,279.997,549.907,549.937,,,,,
13.2186,13.2183,6.66848,280.005,549.934,549.946,,,,,
13.6353,13.635,6.67469,280.002,549.986,550.015,,,,,
14.052,14.0516,6.67684,280.009,549.857,549.861,,,,,
14.4686,14.4683,6.6736,280.008,549.863,549.849,,,,,
14.8853,14.885,6.67324,279.995,549.928,549.905,,,,,
15.302,15.3016,6.67465,279.996,549.916,549.894,,,,,
15.7186,15.7183,6.68269,280.001,549.958,549.971,,,,,
16.1353,16.135,6.68997,279.996,549.955,549.981,,,,,
16.552,16.5516,6.68655,279.998,549.938,549.961,,,,,
16.9686,16.9683,6.6917,280.008,549.936,549.941,,,,,
17.3853,17.385,6.68784,280.006,549.844,549.848,,,,,
17.802,17.8016,6.68487,280.004,549.846,549.855,,,,,
18.2186,18.2183,6.69312,279.998,549.883,549.892,,,,,
18.6353,18.635,6.69777,279.992,549.859,549.86,,,,,
19.052,19.0516,6.70008,280,549.861,549.86,,,,,
19.4686,19.4683,6.70299,280.005,549.925,549.891,,,,,
19.8853,19.885,6.6963,279.991,549.902,549.866,,,,,
20.302,20.3016,6.69752,280,549.85,549.796,,,,,
20.7186,20.7183,6.69718,279.998,549.941,549.893,,,,,
21.1353,21.135,6.69906,280,549.932,549.91,,,,,
21.552,21.5516,6.70341,280,549.852,549.836,,,,,
21.9686,21.9683,6.7116,280.005,549.985,549.979,,,,,
22.3853,22.385,6.70868,279.993,549.942,549.941,,,,,
22.802,22.8016,6.71423,280.003,549.932,549.937,,,,,
23.2186,23.2183,6.70643,279.997,549.859,549.878,,,,,
23.6353,23.635,6.70562,280.006,549.88,549.877,,,,,
24.052,24.0516,6.70859,280.005,549.871,549.898,,,,,
24.4686,24.4683,6.71546,280.011,549.897,549.909,,,,,
24.8853,24.885,6.71797,280.002,549.875,549.872,,,,,
25.302,25.3016,6.71777,280,549.896,549.894,,,,,
25.7186,25.7183,6.71344,279.99,549.895,549.88,,,,,
26.1353,26.135,6.71553,279.993,549.932,549.894,,,,,
26.552,26.5516,6.71282,280.002,550.015,549.981,,,,,
26.9686,26.9683,6.70979,280.001,549.944,549.93,,,,,
27.3853,27.385,6.71841,280.001,549.811,549.814,,,,,
27.802,27.8016,6.7139,279.999,549.802,549.791,,,,,
28.2186,28.2183,6.71531,279.996,549.988,549.985,,,,,
28.6353,28.635,6.72101,279.996,549.986,549.998,,,,,
29.052,29.0516,6.72095,279.988,549.889,549.88,,,,,
29.4686,29.4683,6.71881,280.001,549.853,549.839,,,,,
29.8853,29.885,6.7196,279.999,549.91,549.903,,,,,
30.302,30.3016,6.72062,280.002,549.989,549.987,,,,,
30.7186,30.7183,6.72019,279.996,549.919,549.921,,,,,
31.1353,31.135,6.72409,279.998,549.963,549.982,,,,,
31.552,31.5516,6.72593,279.997,549.923,549.934,,,,,
31.9686,31.9683,6.72845,279.999,549.933,549.986,,,,,
32.3853,32.385,6.72662,280.001,549.962,549.983,,,,,
32.802,32.8016,6.72436,280.005,549.938,549.97,,,,,
33.2186,33.2183,6.72371,280.006,549.947,549.977,,,,,
33.6353,33.635,6.72672,279.999,549.807,549.834,,,,,
34.052,34.0516,6.72874,279.999,549.807,549.812,,,,,
34.4686,34.4683,6.73031,279.999,549.847,549.849,,,,,
34.8853,34.885,6.73261,279.996,550.013,550.014,,,,,
35.302,35.3016,6.73278,279.994,549.902,549.887,,,,,
35.7186,35.7183,6.73286,280,549.886,549.859,,,,,
36.1353,36.135,6.73671,279.999,549.928,549.905,,,,,
36.552,36.5516,6.73943,279.994,549.904,549.91,,,,,
36.9686,36.9683,6.74398,279.997,549.984,549.967,,,,,
37.3853,37.385,6.74334,280.008,549.913,549.902,,,,,
37.802,37.8016,6.7421,280,549.879,549.878,,,,,
38.2186,38.2183,6.74525,280.008,549.836,549.837,,,,,
38.6353,38.635,6.74203,280.007,549.884,549.886,,,,,
39.052,39.0516,6.7413,280.004,549.971,549.966,,,,,
39.4686,39.4683,6.74383,280.004,549.904,549.891,,,,,
39.8853,39.885,6.75295,280.001,549.908,549.917,,,,,
40.302,40.3016,6.75137,279.995,549.967,549.957,,,,,
40.7186,40.7183,6.75593,279.998,549.941,549.95,,,,,
41.1353,41.135,6.75504,279.997,549.98,549.997,,,,,
41.552,41.5516,6.75571,279.999,549.788,549.802,,,,,
41.9686,41.9683,6.7606,279.999,549.925,549.938,,,,,
42.3853,42.385,6.76019,279.998,549.87,549.846,,,,,
42.802,42.8016,6.75667,279.994,549.826,549.809,,,,,
43.2186,43.2183,6.74917,280.008,549.862,549.826,,,,,
43.6353,43.635,6.76172,279.998,549.921,549.886,,,,,
44.052,44.0516,6.76065,279.993,549.969,549.951,,,,,
44.4686,44.4683,6.76266,279.999,549.861,549.85,,,,,
44.8853,44.885,6.76068,280.003,549.862,549.847,,,,,
45.302,45.3016,6.76672,279.997,549.888,549.85,,,,,
45.7186,45.7183,6.76154,279.996,549.908,549.864,,,,,
46.1353,46.135,6.77221,279.999,549.867,549.845,,,,,
46.552,46.5516,6.76225,279.998,549.854,549.833,,,,,
46.9686,46.9683,6.76554,280.002,550.019,549.998,,,,,
47.3853,47.385,6.76564,279.996,549.822,549.811,,,,,
47.802,47.8016,6.76471,280.001,549.834,549.828,,,,,
48.2186,48.2183,6.76324,280.005,549.905,549.895,,,,,
48.6353,48.635,6.76236,279.989,549.929,549.926,,,,,
49.052,49.0516,6.75784,279.996,549.888,549.877,,,,,
49.4686,49.4683,6.76213,279.998,549.926,549.936,,,,,
49.8853,49.885,6.76019,280.001,549.893,549.903,,,,,
50.302,50.3016,6.75976,279.991,549.944,549.931,,,,,
50.7186,50.7183,6.76262,279.999,549.979,550.016,,,,,
51.1353,51.135,6.76419,280.002,549.934,549.972,,,,,
51.552,51.5516,6.76437,280.004,549.934,549.963,,,,,
51.9686,51.9683,6.76892,280.005,549.899,549.912,,,,,
52.3853,52.385,6.76927,279.998,549.897,549.9,,,,,
52.802,52.8016,6.76502,279.996,549.913,549.916,,,,,
53.2186,53.2183,6.76456,279.994,549.829,549.827,,,,,
53.6353,53.635,6.76198,280,549.872,549.863,,,,,
54.052,54.0516,6.76768,279.991,549.905,549.897,,,,,
54.4686,54.4683,6.77201,280.008,549.852,549.837,,,,,
54.8853,54.885,6.76797,280.002,549.945,549.914,,,,,
55.302,55.3016,6.76759,280.004,549.944,549.909,,,,,
55.7186,55.7183,6.76688,280.001,549.928,549.921,,,,,
56.1353,56.135,6.76741,279.998,549.904,549.902,,,,,
56.552,56.5516,6.77037,279.999,549.94,549.948,,,,,
56.9686,56.9683,6.77113,280,549.907,549.925,,,,,
57.3853,57.385,6.77689,279.995,549.908,549.932,,,,,
57.802,57.8016,6.77503,279.997,549.962,549.976,,,,,
58.2186,58.2183,6.77687,280.003,549.968,550.003,,,,,
58.6353,58.635,6.77617,279.992,549.779,549.794,,,,,
59.052,59.0516,6.77365,280.001,549.849,549.865,,,,,
59.4686,59.4683,6.77377,279.994,549.907,549.894,,,,,
59.8853,59.885,6.77191,279.999,550.025,550,,,,,
60.302,60.3016,6.77515,280.002,549.822,549.828,,,,,
60.7186,60.7183,6.78069,279.99,549.932,549.944,,,,,
61.1353,61.135,6.78411,280.007,550.008,549.997,,,,,
61.552,61.5516,6.78457,280.006,549.862,549.861,,,,,
61.9686,61.9683,6.78181,280.002,549.924,549.911,,,,,
62.3853,62.385,6.78074,280.001,550.001,549.989,,,,,
62.802,62.8016,6.77743,280,549.972,549.974,,,,,
63.2186,63.2183,6.77844,279.997,549.845,549.843,,,,,
63.6353,63.635,6.78077,279.997,549.873,549.874,,,,,
64.052,64.0516,6.78129,279.995,549.752,549.753,,,,,
64.4686,64.4683,6.78129,279.999,549.898,549.878,,,,,
64.8853,64.885,6.78302,280.009,549.924,549.937,,,,,
65.302,65.3016,6.78941,280.007,549.943,549.952,,,,,
65.7186,65.7183,6.79174,280,549.935,549.951,,,,,
66.1353,66.135,6.79323,279.998,549.887,549.891,,,,,
66.552,66.5516,6.79213,279.994,549.926,549.906,,,,,
66.9686,66.9683,6.78831,280.004,549.921,549.915,,,,,
67.3853,67.385,6.7879,279.994,549.82,549.81,,,,,
67.802,67.8016,6.78498,279.995,549.818,549.801,,,,,
68.2186,68.2183,6.78674,280.009,549.866,549.847,,,,,
68.6353,68.635,6.79299,280.005,549.981,549.953,,,,,
69.052,69.0516,6.79698,280.006,549.981,549.989,,,,,
69.4686,69.4683,6.8017,279.993,549.91,549.928,,,,,
69.8853,69.885,6.79928,280.002,550.008,550.014,,,,,
70.302,70.3016,6.79595,279.999,550.001,550.024,,,,,
70.7186,70.7183,6.80259,280.004,549.815,549.837,,,,,
71.1353,71.135,6.80124,280.001,549.817,549.825,,,,,
71.552,71.5516,6.79195,279.987,549.929,549.905,,,,,
71.9686,71.9683,6.7937,280.001,549.977,549.951,,,,,
72.3853,72.385,6.79174,279.997,549.838,549.815,,,,,
72.802,72.8016,6.789,280.003,549.957,549.947,,,,,
73.2186,73.2183,6.79256,279.995,549.862,549.875,,,,,
73.6353,73.635,6.80442,279.997,549.924,549.927,,,,,
74.052,74.0516,6.79906,279.997,549.877,549.865,,,,,
74.4686,74.4683,6.80586,279.999,549.897,549.899,,,,,
74.8853,74.885,6.80116,279.996,549.907,549.887,,,,,
75.302,75.3016,6.79803,279.993,549.928,549.909,,,,,
75.7186,75.7183,6.79649,280.003,549.991,549.979,,,,,
76.1353,76.135,6.79987,280.005,549.953,549.976,,,,,
76.552,76.5516,6.80322,279.998,549.926,549.946,,,,,
76.9686,76.9683,6.80383,280.004,549.873,549.878,,,,,
77.3853,77.385,6.81015,280,549.897,549.909,,,,,
77.802,77.8016,6.80558,280.007,549.885,549.878,,,,,
78.2186,78.2183,6.80888,280.004,549.88,549.894,,,,,
78.6353,78.635,6.81141,279.992,549.885,549.884,,,,,
79.052,79.0516,6.80784,279.998,549.958,549.953,,,,,
79.4686,79.4683,6.79897,279.997,549.96,549.926,,,,,
79.8853,79.885,6.79796,280.001,549.969,549.962,,,,,
80.302,80.3016,6.8046,279.995,549.955,549.977,,,,,
80.7186,80.7183,6.80391,280.009,550.014,550.043,,,,,
81.1353,81.135,6.805,279.996,549.787,549.813,,,,,
81.552,81.5516,6.79813,280.003,549.796,549.807,,,,,
81.9686,81.9683,6.80077,280,550.007,550.005,,,,,
82.3853,82.385,6.80675,280.002,549.946,549.956,,,,,
82.802,82.8016,6.81339,279.997,549.865,549.879,,,,,
83.2186,83.2183,6.80221,280.001,549.848,549.816,,,,,
83.6353,83.635,6.80433,280,550.055,550.057,,,,,
84.052,84.0516,6.81497,279.992,550.007,550.019,,,,,
84.4686,84.4683,6.81296,279.994,549.884,549.926,,,,,
84.8853,84.885,6.81207,280.007,549.763,549.755,,,,,
85.302,85.3016,6.80202,279.999,549.815,549.805,,,,,
85.7186,85.7183,6.80769,279.995,549.947,549.932,,,,,
86.1353,86.135,6.81752,279.995,550.013,550.008,,,,,
86.552,86.5516,6.8155,280.004,549.939,549.927,,,,,
86.9686,86.9683,6.81367,279.995,549.977,549.968,,,,,
87.3853,87.385,6.80729,280.003,549.934,549.945,,,,,
87.802,87.8016,6.80671,279.997,549.919,549.906,,,,,
88.2186,88.2183,6.80938,280,549.906,549.947,,,,,
88.6353,88.635,6.81571,279.999,549.879,549.907,,,,,
89.052,89.0516,6.81694,280.001,549.813,549.839,,,,,
89.4686,89.4683,6.81507,279.997,549.943,549.965,,,,,
89.8853,89.885,6.80766,279.997,549.895,549.862,,,,,
90.302,90.3016,6.80789,280.002,549.931,549.919,,,,,
90.7186,90.7183,6.8146,279.998,549.891,549.888,,,,,
91.1353,91.135,6.81846,279.997,549.916,549.924,,,,,
91.552,91.5516,6.82152,280.004,549.907,549.893,,,,,
91.9686,91.9683,6.8123,279.997,549.854,549.831,,,,,
92.3853,92.385,6.80927,280.004,549.864,549.858,,,,,
92.802,92.8016,6.81741,280.007,549.951,549.943,,,,,
93.2186,93.2183,6.8188,280.001,549.942,549.932,,,,,
93.6353,93.635,6.8196,279.998,549.845,549.808,,,,,
94.052,94.0516,6.81014,280.007,549.917,549.886,,,,,
94.4686,94.4683,6.81339,279.994,549.921,549.91,,,,,
94.8853,94.885,6.81924,280.003,549.963,549.963,,,,,
95.302,95.3016,6.82481,279.999,549.954,549.969,,,,,
95.7186,95.7183,6.82348,280.002,549.884,549.878,,,,,
96.1353,96.135,6.81242,280.004,549.897,549.891,,,,,
96.552,96.5516,6.82033,280.004,549.869,549.902,,,,,
96.9686,96.9683,6.82364,280.001,549.937,549.965,,,,,
97.3853,97.385,6.8258,280.002,549.879,549.9,,,,,
97.802,97.8016,6.81299,279.998,549.887,549.869,,,,,
98.2186,98.2183,6.81621,280.003,550.024,550.029,,,,,
98.6353,98.635,6.81855,279.999,549.823,549.827,,,,,
99.052,99.0516,6.82663,279.994,549.837,549.855,,,,,
99.4686,99.4683,6.82545,279.994,549.939,549.96,,,,,
99.8853,99.885,6.82136,280.003,549.937,549.93,,,,,
100.302,100.302,6.81863,279.996,549.845,549.829,,,,,
100.719,100.718,6.81651,280.001,549.894,549.888,,,,,
101.135,101.135,6.82568,280.003,550.002,550.013,,,,,
101.552,101.552,6.82841,280.008,549.922,549.944,,,,,
101.969,101.968,6.82738,280.008,549.891,549.908,,,,,
102.385,102.385,6.82661,280,549.879,549.888,,,,,
102.802,102.802,6.8194,280.001,549.815,549.79,,,,,
103.219,103.218,6.8247,280.001,549.949,549.958,,,,,
103.635,103.635,6.82474,280.001,549.943,549.933,,,,,
104.052,104.052,6.82885,280,550.016,550.038,,,,,
104.469,104.468,6.82627,279.992,549.888,549.896,,,,,
104.885,104.885,6.82202,280.005,549.814,549.823,,,,,
105.302,105.302,6.82285,279.997,549.912,549.936,,,,,
105.719,105.718,6.82792,280.006,549.907,549.915,,,,,
106.135,106.135,6.8345,280.005,549.996,550.012,,,,,
106.552,106.552,6.82492,280.002,549.911,549.924,,,,,
106.969,106.968,6.82309,279.998,549.89,549.885,,,,,
107.385,107.385,6.82248,280.005,549.801,549.79,,,,,
107.802,107.802,6.82848,280.005,549.947,549.94,,,,,
108.219,108.218,6.83517,279.999,549.957,549.964,,,,,
108.635,108.635,6.83219,279.993,549.907,549.907,,,,,
109.052,109.052,6.83488,279.995,549.923,549.928,,,,,
109.469,109.468,6.82353,280,549.986,549.972,,,,,
109.885,109.885,6.82589,279.999,549.825,549.823,,,,,
110.302,110.302,6.82958,279.991,549.862,549.862,,,,,
110.719,110.718,6.83434,280.009,549.93,549.943,,,,,
111.135,111.135,6.83458,279.997,549.952,549.956,,,,,
111.552,111.552,6.82965,279.994,549.936,549.93,,,,,
111.969,111.968,6.82588,279.994,549.945,549.955,,,,,
112.385,112.385,6.83308,279.999,549.935,549.953,,,,,
112.802,112.802,6.83565,279.995,549.927,549.963,,,,,
113.219,113.218,6.84117,280,549.895,549.936,,,,,
113.635,113.635,6.83974,280.005,549.928,549.965,,,,,
114.052,114.052,6.82976,280.01,549.779,549.807,,,,,
114.469,114.468,6.82977,279.995,549.814,549.827,,,,,
114.885,114.885,6.83604,279.998,549.909,549.894,,,,,
115.302,115.302,6.83319,280.001,549.925,549.911,,,,,
115.719,115.718,6.84274,279.997,549.957,549.951,,,,,
116.135,116.135,6.83644,280.005,549.905,549.881,,,,,
116.552,116.552,6.83281,280.001,549.879,549.835,,,,,
116.969,116.968,6.83084,280.001,549.96,549.924,,,,,
117.385,117.385,6.83365,279.993,550.032,550.024,,,,,
117.802,117.802,6.84435,279.998,549.994,550.001,,,,,
118.219,118.218,6.83796,279.997,549.864,549.9,,,,,
118.635,118.635,6.84127,280.006,549.903,549.924,,,,,
119.052,119.052,6.83468,280,549.852,549.85,,,,,
119.469,119.468,6.83309,280.003,549.859,549.848,,,,,
119.885,119.885,6.83397,279.999,549.874,549.853,,,,,
120.302,120.302,6.83704,279.999,549.936,549.931,,,,,
120.719,120.718,6.83749,280.002,549.922,549.916,,,,,
121.135,121.135,6.84751,280.002,549.792,549.784,,,,,
121.552,121.552,6.84347,280.002,549.9,549.892,,,,,
121.969,121.968,6.84009,279.999,549.943,549.904,,,,,
122.385,122.385,6.8344,280.005,549.897,549.883,,,,,
122.802,122.802,6.83811,280.007,549.922,549.911,,,,,
123.219,123.218,6.84128,280.002,549.937,549.927,,,,,
123.635,123.635,6.84666,279.997,549.933,549.951,,,,,
124.052,124.052,6.84512,280,549.892,549.904,,,,,
124.469,124.468,6.8378,279.993,549.851,549.855,,,,,
124.885,124.885,6.83766,279.997,549.878,549.866,,,,,
125.302,125.302,6.84062,280,549.926,549.925,,,,,
125.719,125.718,6.84539,280.001,549.857,549.88,,,,,
126.135,126.135,6.84341,279.995,549.926,549.922,,,,,
126.552,126.552,6.84895,280.005,549.943,549.947,,,,,
126.969,126.968,6.84689,279.993,549.948,549.929,,,,,
127.385,127.385,6.84008,280.006,549.908,549.897,,,,,
127.802,127.802,6.83864,279.999,549.937,549.95,,,,,
128.219,128.218,6.84855,280.005,549.95,549.969,,,,,
128.635,128.635,6.84639,280.003,549.929,549.945,,,,,
129.052,129.052,6.85036,279.996,549.986,550.03,,,,,
129.469,129.468,6.8438,280.004,549.754,549.776,,,,,
129.885,129.885,6.83949,279.998,549.896,549.886,,,,,
130.302,130.302,6.84016,280,549.968,549.945,,,,,
130.719,130.718,6.84685,280.001,549.862,549.863,,,,,
131.135,131.135,6.84832,280.001,549.914,549.911,,,,,
131.552,131.552,6.8517,279.992,549.924,549.917,,,,,
131.969,131.968,6.85513,279.999,549.961,549.971,,,,,
132.385,132.385,6.84984,279.999,549.94,549.933,,,,,
132.802,132.802,6.84233,280,549.838,549.819,,,,,
133.219,133.218,6.84264,280.007,549.88,549.869,,,,,
133.635,133.635,6.8447,279.991,549.91,549.905,,,,,
134.052,134.052,6.85336,280.003,549.933,549.928,,,,,
134.469,134.468,6.85063,279.994,549.924,549.932,,,,,
134.885,134.885,6.85222,280.005,549.923,549.914,,,,,
135.302,135.302,6.85097,280.01,549.896,549.866,,,,,
135.719,135.718,6.8431,279.996,549.929,549.917,,,,,
136.135,136.135,6.8469,280.004,549.924,549.939,,,,,
136.552,136.552,6.8531,279.996,549.923,549.933,,,,,
136.969,136.968,6.85258,279.997,549.928,549.95,,,,,
137.385,137.385,6.84979,279.999,549.913,549.912,,,,,
137.802,137.802,6.84273,279.996,549.869,549.88,,,,,
138.219,138.218,6.85273,280,549.917,549.933,,,,,
138.635,138.635,6.8568,280.005,549.886,549.884,,,,,
139.052,139.052,6.8544,279.989,549.896,549.921,,,,,
139.469,139.468,6.85383,279.997,549.844,549.812,,,,,
139.885,139.885,6.84408,280,549.889,549.838,,,,,
140.302,140.302,6.8512,279.997,549.963,549.949,,,,,
140.719,140.718,6.85561,279.996,549.833,549.821,,,,,
141.135,141.135,6.85421,280.002,549.984,549.981,,,,,
141.552,141.552,6.85622,280.002,549.983,549.972,,,,,
141.969,141.968,6.85373,280.008,549.84,549.831,,,,,
142.385,142.385,6.85074,280.005,549.836,549.827,,,,,
142.802,142.802,6.85104,280.004,549.932,549.948,,,,,
143.219,143.218,6.85388,280,550.014,550.024,,,,,
143.635,143.635,6.85601,279.998,549.984,549.991,,,,,
144.052,144.052,6.85502,280.001,549.884,549.908,,,,,
144.469,144.468,6.85779,279.997,549.88,549.903,,,,,
144.885,144.885,6.85373,280.003,549.787,549.812,,,,,
145.302,145.302,6.85192,280.002,549.869,549.896,,,,,
145.719,145.718,6.84242,279.999,549.893,549.873,,,,,
146.135,146.135,6.85561,279.998,549.881,549.888,,,,,
146.552,146.552,6.83621,280.005,549.926,549.915,,,,,
146.969,146.968,6.84511,279.994,550.004,549.996,,,,,
147.385,147.385,6.84417,279.993,549.854,549.879,,,,,
147.802,147.802,6.85662,280.008,549.916,549.939,,,,,
148.219,148.218,6.84434,280.001,549.951,549.962,,,,,
148.635,148.635,6.84059,279.999,549.919,549.949,,,,,
149.052,149.052,6.83927,279.997,549.922,549.934,,,,,
149.469,149.468,6.84396,279.997,549.866,549.902,,,,,
149.885,149.885,6.84163,280,549.779,549.758,,,,,
150.302,150.302,6.83792,279.999,549.906,549.893,,,,,
150.719,150.718,6.84266,280.003,549.998,550.004,,,,,
151.135,151.135,6.85155,279.997,550.058,550.049,,,,,
151.552,151.552,6.84924,279.996,549.912,549.931,,,,,
151.969,151.968,6.8438,280.003,549.923,549.929,,,,,
152.385,152.385,6.83889,279.997,549.968,549.974,,,,,
152.802,152.802,6.8393,280.006,549.882,549.915,,,,,
153.219,153.218,6.84439,280.002,549.735,549.756,,,,,
153.635,153.635,6.85188,279.996,549.886,549.894,,,,,
154.052,154.052,6.84497,279.996,550.019,549.998,,,,,
154.469,154.468,6.84013,280,549.9,549.887,,,,,
154.885,154.885,6.84024,279.994,549.97,549.973,,,,,
155.302,155.302,6.84639,279.999,549.906,549.912,,,,,
155.719,155.718,6.8485,279.999,549.94,549.962,,,,,
156.135,156.135,6.84709,280.006,549.827,549.82,,,,,
156.552,156.552,6.84306,279.997,549.933,549.922,,,,,
156.969,156.968,6.84807,280.005,549.996,550.008,,,,,
157.385,157.385,6.85046,279.996,549.955,549.983,,,,,
157.802,157.802,6.84999,279.998,549.859,549.876,,,,,
158.219,158.218,6.85338,279.999,549.816,549.843,,,,,
158.635,158.635,6.8495,280.004,549.852,549.844,,,,,
159.052,159.052,6.84689,280.001,549.895,549.858,,,,,
159.469,159.468,6.84628,280.004,549.922,549.908,,,,,
159.885,159.885,6.847,279.999,550.043,550.026,,,,,
160.302,160.302,6.85388,280.006,549.956,549.962,,,,,
160.719,160.718,6.85821,279.996,549.971,549.996,,,,,
161.135,161.135,6.85697,280,549.823,549.851,,,,,
161.552,161.552,6.85143,280.001,549.814,549.828,,,,,
161.969,161.968,6.85289,280.003,549.854,549.832,,,,,
162.385,162.385,6.84679,280.007,549.923,549.89,,,,,
162.802,162.802,6.84893,279.994,549.891,549.865,,,,,
163.219,163.218,6.84854,280.003,550.005,549.975,,,,,
163.635,163.635,6.85361,280.002,549.915,549.904,,,,,
164.052,164.052,6.86238,280,549.915,549.906,,,,,
164.469,164.468,6.85881,279.999,549.822,549.846,,,,,
164.885,164.885,6.8558,280,549.977,549.981,,,,,
165.302,165.302,6.85143,279.996,549.873,549.877,,,,,
165.719,165.718,6.85977,279.988,549.939,549.939,,,,,
166.135,166.135,6.86302,280.003,549.93,549.963,,,,,
166.552,166.552,6.85734,280.009,549.801,549.832,,,,,
166.969,166.968,6.85412,280.002,549.906,549.891,,,,,
167.385,167.385,6.85015,280.002,549.825,549.794,,,,,
167.802,167.802,6.85355,279.997,549.992,549.96,,,,,
168.219,168.218,6.85876,280.002,549.865,549.828,,,,,
168.635,168.635,6.85129,279.994,549.83,549.816,,,,,
169.052,169.052,6.8584,280.001,549.873,549.883,,,,,
169.469,169.468,6.85676,279.998,549.931,549.933,,,,,
169.885,169.885,6.84923,279.998,549.936,549.935,,,,,
170.302,170.302,6.84619,280.004,549.945,549.951,,,,,
170.719,170.718,6.84964,280.003,549.961,549.957,,,,,
171.135,171.135,6.84681,279.999,549.816,549.838,,,,,
171.552,171.552,6.85397,280.014,549.834,549.823,,,,,
171.969,171.968,6.84821,279.998,549.841,549.839,,,,,
172.385,172.385,6.85542,280.001,549.896,549.891,,,,,
172.802,172.802,6.85338,280.006,549.984,549.949,,,,,
173.219,173.218,6.85208,279.994,549.924,549.916,,,,,
173.635,173.635,6.85377,280.01,549.864,549.859,,,,,
174.052,174.052,6.84774,280,549.965,549.959,,,,,
174.469,174.468,6.86013,279.997,549.934,549.939,,,,,
174.885,174.885,6.85299,279.998,549.911,549.926,,,,,
175.302,175.302,6.86081,280.003,550.007,550.029,,,,,
175.719,175.718,6.85721,280.001,549.959,549.971,,,,,
176.135,176.135,6.86004,280.008,549.995,550.067,,,,,
176.552,176.552,6.8588,280.001,549.784,549.818,,,,,
176.969,176.968,6.85364,280,549.821,549.847,,,,,
177.385,177.385,6.85593,280.007,549.875,549.917,,,,,
177.802,177.802,6.85816,280.003,549.974,549.975,,,,,
178.219,178.218,6.85455,280.006,549.962,549.957,,,,,
178.635,178.635,6.85176,280.001,549.9,549.909,,,,,
179.052,179.052,6.85075,280.005,549.892,549.881,,,,,
179.469,179.468,6.84493,280.004,549.831,549.816,,,,,
179.885,179.885,6.84743,280,549.91,549.899,,,,,
180.302,180.302,6.85417,280.003,549.882,549.873,,,,,
180.719,180.718,6.855,279.999,550.052,550.03,,,,,
181.135,181.135,6.85435,280.005,549.976,549.984,,,,,
181.552,181.552,6.85748,280,549.914,549.932,,,,,
181.969,181.968,6.84977,279.993,549.734,549.732,,,,,
182.385,182.385,6.8482,280.003,549.916,549.895,,,,,
182.802,182.802,6.85937,280.005,550.042,550.025,,,,,
183.219,183.218,6.85653,279.996,549.971,549.987,,,,,
183.635,183.635,6.85647,280.001,549.896,549.921,,,,,
184.052,184.052,6.85488,279.997,549.873,549.885,,,,,
184.469,184.468,6.8539,280.004,549.909,549.9,,,,,
184.885,184.885,6.85613,280,549.915,549.889,,,,,
185.302,185.302,6.85755,280.002,549.812,549.809,,,,,
185.719,185.718,6.86316,280.006,549.914,549.909,,,,,
186.135,186.135,6.86351,279.997,549.907,549.898,,,,,
186.552,186.552,6.85998,279.999,549.887,549.88,,,,,
186.969,186.968,6.85682,279.995,549.883,549.857,,,,,
187.385,187.385,6.8532,280.003,549.881,549.846,,,,,
187.802,187.802,6.85591,280,549.988,549.932,,,,,
188.219,188.218,6.85867,279.997,549.96,549.937,,,,,
188.635,188.635,6.85861,280.001,549.854,549.828,,,,,
189.052,189.052,6.85848,280.002,549.96,549.951,,,,,
189.469,189.468,6.86236,280.005,549.972,549.945,,,,,
189.885,189.885,6.86265,280.001,549.903,549.919,,,,,
190.302,190.302,6.86812,280.001,549.817,549.841,,,,,
190.719,190.718,6.87038,279.995,549.83,549.839,,,,,
191.135,191.135,6.87369,279.996,549.898,549.877,,,,,
191.552,191.552,6.86532,279.997,549.936,549.904,,,,,
191.969,191.968,6.86406,280.006,549.918,549.887,,,,,
192.385,192.385,6.86918,280.002,549.977,549.951,,,,,
192.802,192.802,6.86659,280.002,549.87,549.857,,,,,
193.219,193.218,6.86158,280.005,549.922,549.907,,,,,
193.635,193.635,6.85752,279.997,549.885,549.844,,,,,
194.052,194.052,6.85874,280.005,549.911,549.9,,,,,
194.469,194.468,6.85771,280.003,549.896,549.908,,,,,
194.885,194.885,6.85151,280.003,549.863,549.861,,,,,
195.302,195.302,6.85315,279.991,549.972,549.985,,,,,
195.719,195.718,6.85211,280.005,549.931,549.941,,,,,
196.135,196.135,6.85365,280.008,549.805,549.829,,,,,
196.552,196.552,6.85758,279.999,549.848,549.847,,,,,
196.969,196.968,6.85454,279.996,549.948,549.937,,,,,
197.385,197.385,6.85556,280.003,549.975,549.962,,,,,
197.802,197.802,6.855,280.006,549.93,549.919,,,,,
198.219,198.218,6.86342,279.998,549.962,549.971,,,,,
198.635,198.635,6.86123,279.999,549.905,549.916,,,,,
199.052,199.052,6.8597,280.007,549.907,549.899,,,,,
199.469,199.468,6.85898,279.997,549.91,549.909,,,,,
199.885,199.885,6.86248,279.995,549.992,549.986,,,,,
200.302,200.302,6.86046,279.989,549.813,549.849,,,,,
200.719,200.718,6.85914,280.004,549.888,549.915,,,,,
201.135,201.135,6.85662,280.001,549.975,549.989,,,,,
201.552,201.552,6.85855,279.996,549.972,549.999,,,,,
201.969,201.968,6.85983,279.993,549.955,549.976,,,,,
202.385,202.385,6.85612,280.005,549.891,549.906,,,,,
202.802,202.802,6.85683,280.001,549.949,549.955,,,,,
203.219,203.218,6.85523,279.997,549.872,549.85,,,,,
203.635,203.635,6.8575,280.001,549.824,549.812,,,,,
203.651,203.65,6.86012,278.555,549.82,549.82,,,,,
203.651,203.65,6.85875,276.706,549.82,549.82,,,,,
203.651,203.65,6.85739,274.849,549.837,549.82,,,,,
203.651,203.651,6.85604,273.035,549.837,549.82,,,,,
203.651,203.651,6.85475,271.25,549.837,549.82,,,,,
203.651,203.651,6.85366,269.449,549.828,549.82,,,,,
203.651,203.651,6.85249,267.658,549.828,549.82,,,,,
203.651,203.651,6.85119,265.821,549.828,549.805,,,,,
203.651,203.651,6.85004,263.94,549.828,549.805,,,,,
203.651,203.651,6.84888,262.026,549.84,549.805,,,,,
203.651,203.651,6.84748,260.072,549.84,549.805,,,,,
203.651,203.651,6.84645,258.094,549.84,549.805,,,,,
203.652,203.651,6.84521,256.11,549.829,549.805,,,,,
203.652,203.651,6.844,254.236,549.829,549.818,,,,,
203.652,203.651,6.84259,252.193,549.829,549.818,,,,,
203.652,203.651,6.84126,250.183,549.84,549.818,,,,,
203.652,203.652,6.83995,248.145,549.84,549.818,,,,,
203.652,203.652,6.83863,246.211,549.84,549.816,,,,,
203.652,203.652,6.83743,244.466,549.84,549.816,,,,,
203.652,203.652,6.83622,242.64,549.84,549.816,,,,,
203.652,203.652,6.83482,240.862,549.84,549.82,,,,,
203.652,203.652,6.8337,239.037,549.84,549.82,,,,,
203.652,203.652,6.8324,237.254,549.84,549.82,,,,,
203.652,203.652,6.83117,235.456,549.848,549.82,,,,,
203.652,203.652,6.82969,233.666,549.848,549.823,,,,,
203.653,203.652,6.82825,231.873,549.848,549.823,,,,,
203.653,203.652,6.82691,230.103,549.848,549.823,,,,,
203.653,203.652,6.82548,228.171,549.846,549.823,,,,,
203.653,203.652,6.82429,226.395,549.846,549.82,,,,,
203.653,203.653,6.82287,224.618,549.846,549.82,,,,,
203.653,203.653,6.82171,222.787,549.846,549.82,,,,,
203.653,203.653,6.8203,220.945,549.861,549.82,,,,,
203.653,203.653,6.81895,219.19,549.861,549.826,,,,,
203.653,203.653,6.8174,217.188,549.861,549.826,,,,,
203.653,203.653,6.8161,215.44,549.861,549.826,,,,,
203.653,203.653,6.81474,213.681,549.847,549.826,,,,,
203.653,203.653,6.81349,211.808,549.847,549.821,,,,,
203.653,203.653,6.81231,209.993,549.847,549.821,,,,,
203.653,203.653,6.81058,207.992,549.85,549.821,,,,,
203.654,203.653,6.809,205.966,549.85,549.821,,,,,
203.654,203.653,6.80777,204.097,549.85,549.829,,,,,
203.654,203.653,6.80658,202.277,549.85,549.829,,,,,
203.654,203.653,6.80529,200.293,549.855,549.829,,,,,
203.654,203.654,6.8041,198.238,549.855,549.836,,,,,
203.654,203.654,6.80294,196.207,549.855,549.836,,,,,
203.654,203.654,6.80175,194.216,549.855,549.836,,,,,
203.654,203.654,6.80054,192.354,549.855,549.836,,,,,
203.654,203.654,6.79908,190.307,549.855,549.844,,,,,
203.654,203.654,6.79762,188.276,549.855,549.844,,,,,
203.654,203.654,6.79639,186.238,549.871,549.844,,,,,
203.654,203.654,6.79508,184.204,549.871,549.836,,,,,
203.655,203.654,6.79385,182.149,549.871,549.836,,,,,
203.655,203.654,6.79256,180.119,549.865,549.836,,,,,
203.655,203.654,6.79141,178.106,549.865,549.84,,,,,
203.655,203.654,6.79024,176.107,549.865,549.84,,,,,
203.655,203.655,6.78894,174.069,549.865,549.84,,,,,
203.655,203.655,6.78757,172.024,549.865,549.84,,,,,
203.655,203.655,6.78612,169.994,549.865,549.847,,,,,
203.655,203.655,6.78476,167.992,549.865,549.847,,,,,
203.655,203.655,6.78364,166.002,549.868,549.847,,,,,
203.655,203.655,6.78241,163.969,549.868,549.842,,,,,
203.655,203.655,6.78092,161.961,549.868,549.842,,,,,
203.655,203.655,6.77963,159.936,549.876,549.842,,,,,
203.656,203.655,6.7783,157.92,549.876,549.842,,,,,
203.656,203.655,6.77685,155.906,549.876,549.842,,,,,
203.656,203.655,6.7754,153.863,549.881,549.842,,,,,
203.656,203.655,6.77407,151.828,549.881,549.842,,,,,
203.656,203.656,6.77281,149.831,549.881,549.838,,,,,
203.656,203.656,6.77136,147.845,549.881,549.838,,,,,
203.656,203.656,6.7699,145.869,549.882,549.838,,,,,
203.656,203.656,6.76857,143.883,549.882,549.856,,,,,
203.656,203.656,6.76732,141.863,549.882,549.856,,,,,
203.656,203.656,6.76611,139.877,549.884,549.856,,,,,
203.656,203.656,6.76487,137.898,549.884,549.856,,,,,
203.656,203.656,6.76345,135.899,549.884,549.862,,,,,
203.657,203.656,6.76209,133.895,549.883,549.862,,,,,
203.657,203.656,6.76091,131.895,549.883,549.862,,,,,
203.657,203.656,6.75979,129.906,549.883,549.87,,,,,
203.657,203.656,6.75858,127.926,549.883,549.87,,,,,
203.657,203.657,6.7574,125.949,549.891,549.87,,,,,
203.657,203.657,6.75634,123.941,549.891,549.857,,,,,
203.657,203.657,6.75509,121.954,549.891,549.857,,,,,
203.657,203.657,6.75386,119.983,549.895,549.857,,,,,
203.657,203.657,6.7525,118.043,549.895,549.86,,,,,
203.657,203.657,6.7512,116.085,549.895,549.86,,,,,
203.657,203.657,6.74997,114.107,549.895,549.86,,,,,
203.657,203.657,6.74889,112.13,549.89,549.86,,,,,
203.658,203.657,6.74775,110.171,549.89,549.869,,,,,
203.658,203.657,6.74667,108.236,549.89,549.869,,,,,
203.658,203.657,6.74546,106.302,549.9,549.869,,,,,
203.658,203.657,6.74408,104.353,549.9,549.873,,,,,
203.658,203.658,6.74286,102.405,549.9,549.873,,,,,
203.658,203.658,6.74178,100.479,549.907,549.873,,,,,
203.658,203.658,6.74064,98.5661,549.907,549.885,,,,,
203.658,203.658,6.73954,96.6209,549.907,549.885,,,,,
203.658,203.658,6.73845,94.6949,549.907,549.885,,,,,
203.658,203.658,6.73726,92.7735,549.905,549.885,,,,,
203.658,203.658,6.73594,90.8595,549.905,549.886,,,,,
203.658,203.658,6.73466,88.9573,549.905,549.886,,,,,
203.659,203.658,6.73349,87.0339,549.927,549.886,,,,,
203.659,203.658,6.73245,85.1123,549.927,549.891,,,,,
203.659,203.658,6.73133,83.202,549.927,549.891,,,,,
203.659,203.658,6.73012,81.3229,549.931,549.891,,,,,
203.659,203.659,6.72902,79.4351,549.931,549.891,,,,,
203.659,203.659,6.72793,77.5376,549.931,549.893,,,,,
203.659,203.659,6.72676,75.6408,549.935,549.893,,,,,
203.659,203.659,6.72556,73.752,549.935,549.893,,,,,
203.659,203.659,6.72453,71.9214,549.935,549.896,,,,,
203.659,203.659,6.72342,70.0535,549.935,549.896,,,,,
203.659,203.659,6.72222,68.1629,549.933,549.896,,,,,
203.659,203.659,6.72119,66.2849,549.933,549.899,,,,,
203.66,203.659,6.72002,64.4247,549.933,549.899,,,,,
203.66,203.659,6.71892,62.5927,549.935,549.899,,,,,
203.66,203.659,6.71783,60.7564,549.935,549.9,,,,,
203.66,203.659,6.7167,58.8873,549.935,549.9,,,,,
203.66,203.66,6.71545,57.0301,549.931,549.9,,,,,
203.66,203.66,6.71433,55.1963,549.931,549.9,,,,,
203.66,203.66,6.7133,53.3806,549.931,549.91,,,,,
203.66,203.66,6.71232,51.5507,549.931,549.91,,,,,
203.66,203.66,6.71125,49.7379,549.933,549.91,,,,,
203.66,203.66,6.71019,47.9331,549.933,549.909,,,,,
203.66,203.66,6.70914,46.1212,549.933,549.909,,,,,
203.66,203.66,6.70816,44.3415,549.947,549.909,,,,,
203.661,203.66,6.70719,42.5424,549.947,549.907,,,,,
203.661,203.66,6.70626,40.7345,549.947,549.907,,,,,
203.661,203.66,6.70509,38.9324,549.947,549.907,,,,,
203.661,203.66,6.70402,37.1644,549.95,549.907,,,,,
203.661,203.661,6.70301,35.3475,549.95,549.91,,,,,
203.661,203.661,6.70203,33.5724,549.95,549.91,,,,,
203.661,203.661,6.70106,31.7981,549.947,549.91,,,,,
203.661,203.661,6.70008,30.0285,549.947,549.917,,,,,
203.661,203.661,6.69884,28.1322,549.947,549.917,,,,,
203.661,203.661,6.69783,26.2971,549.957,549.917,,,,,
203.661,203.661,6.69665,24.4446,549.957,549.913,,,,,
203.661,203.661,6.69549,22.5887,549.957,549.913,,,,,
203.662,203.661,6.69439,20.7912,549.959,549.913,,,,,
203.662,203.661,6.69318,18.8153,549.959,549.925,,,,,
203.662,203.661,6.6919,16.8602,549.959,549.925,,,,,
203.662,203.662,6.69074,14.9329,549.961,549.925,,,,,
203.662,203.662,6.6896,12.9548,549.961,549.926,,,,,
203.662,203.662,6.68846,11.0084,549.961,549.926,,,,,
203.662,203.662,6.68706,9.06222,549.962,549.926,,,,,
203.662,203.662,6.68568,7.11106,549.962,549.923,,,,,
203.662,203.662,6.68444,5.22304,549.962,549.923,,,,,
203.662,203.662,6.68326,3.37281,549.968,549.923,,,,,
203.663,203.662,6.68188,1.55762,549.968,549.938,,,,,
204.079,204.079,6.59114,1.22999,511.211,510.01,,,,,
204.496,204.496,6.49948,1.24093,471.406,469.646,,,,,
204.913,204.912,6.4349,1.24918,436.001,433.725,,,,,
205.329,205.329,6.37147,1.24341,404.065,401.228,,,,,
205.746,205.746,6.31289,1.24233,375.247,371.988,,,,,
206.163,206.162,6.26023,1.24167,348.581,345.022,,,,,
206.579,206.579,6.21908,1.25213,324.136,320.344,,,,,
206.996,206.996,6.17335,1.24666,301.606,297.674,,,,,
207.413,207.412,6.13349,1.24024,280.834,276.807,,,,,
207.829,207.829,6.1024,1.23908,261.503,257.457,,,,,
208.246,208.246,6.07795,1.24128,243.501,239.405,,,,,
208.663,208.662,6.04163,1.23933,226.836,222.725,,,,,
209.079,209.079,6.01292,1.23755,211.587,207.514,,,,,
209.496,209.496,5.98875,1.23697,197.146,193.159,,,,,
209.913,209.912,5.96516,1.24145,184.06,180.16,,,,,
210.329,210.329,5.94172,1.23607,171.815,168.044,,,,,
210.746,210.746,5.92789,1.2363,160.493,156.846,,,,,
211.163,211.162,5.906,1.23881,149.958,146.51,,,,,
211.579,211.579,5.89894,1.23306,140.225,136.933,,,,,
211.996,211.996,5.879,1.23843,131.248,128.142,,,,,
212.413,212.412,5.86414,1.22719,123.023,120.082,,,,,
212.829,212.829,5.86036,1.23633,115.298,112.584,,,,,
213.246,213.246,5.84396,1.24397,108.296,105.692,,,,,
213.663,213.662,5.8326,1.23585,101.821,99.408,,,,,
214.079,214.079,5.82442,1.23839,95.7923,93.5472,,,,,
214.496,214.496,5.81708,1.2379,90.2087,88.1143,,,,,
214.913,214.912,5.8163,1.22612,85.1212,83.2146,,,,,
215.329,215.329,5.80261,1.24316,80.3578,78.4909,,,,,
215.746,215.746,5.80377,1.23146,75.9615,74.3238,,,,,
216.163,216.162,5.79193,1.24064,72.0081,70.5146,,,,,
216.579,216.579,5.79285,1.24455,68.2345,66.9211,,,,,
216.996,216.996,5.78046,1.23861,64.7427,63.3866,,,,,
217.413,217.412,5.78194,1.23768,61.5672,60.4812,,,,,
217.829,217.829,5.7722,1.23039,58.5883,57.6608,,,,,
218.246,218.246,5.76983,1.23094,55.765,55.0028,,,,,
218.663,218.662,5.767,1.23866,53.1968,52.4476,,,,,
219.079,219.079,5.76711,1.23141,50.7757,50.0668,,,,,
219.496,219.496,5.76465,1.24415,48.5618,48.0525,,,,,
219.913,219.912,5.75974,1.23761,46.5387,46.1428,,,,,
220.329,220.329,5.7548,1.24074,44.6527,44.3058,,,,,
220.746,220.746,5.75406,1.23855,42.8983,42.6136,,,,,
220.829,220.829,5.75226,1.23632,42.5761,42.2798,,,,,