File: Experiment/Experiment/Sample 2 Data/Sample2_320MPa_550C_200h.csv
Date/Clock time,45695.4,,,,,,,,
Tester,"Arik, Cameron",,,,,,,,
Specimen designation,316H-elg_320MPa_550C_02,,,,,,,,
Diameter,6.0475,mm,,,,,,,
Material,316H-elg,,,,,,,,
Load cell,100kN,,,,,,,,
Extensometer,Epsilon 3549 SN102121 GL25mm,,,,,,,,
"Gage length, standard travel",25,mm,,,,,,,
Test standard,ASTM E136,,,,,,,,
Machine data,ZwickRoell Kappa100 SS-CF,,,,,,,,
Time,Test time,Standard travel,Standard force,Temperature,Temperature 3,,,,
h,h,%,MPa,°C,°C,,,,
0.000560979,0.000277778,0.289741,3.68459,22.6128,22.4333,,,,
0.00473876,0.000538889,-0.00229092,2.65035,22.6032,22.4326,,,,
0.301428,0.297228,0.0134191,1.96478,45.7954,44.0964,,,,
0.718094,0.713894,0.173709,1.9535,175.24,173.023,,,,
1.13476,1.13056,0.41352,1.95073,308.743,314.054,,,,
1.55143,1.54723,0.655128,1.95214,433.943,433.279,,,,
1.96809,1.96389,0.890134,1.95749,541.604,537.394,,,,
2.38476,2.38056,0.942872,1.96172,553.277,550.01,,,,
2.80143,2.79723,0.930961,1.9659,548.277,546.169,,,,
3.21809,3.21389,0.931187,1.97769,547.487,546.742,,,,
3.63476,3.63056,0.943389,1.97284,549.291,549.555,,,,
3.81614,0,0.000777948,1.86552,550.012,550.32,,,,
3.81631,0.000177778,0.00330715,3.77511,550.012,550.32,,,,
3.81643,0.000294444,0.00526672,5.61358,550.019,550.321,,,,
3.81656,0.000419444,0.00588609,7.39908,550.019,550.321,,,,
3.81669,0.000558333,0.00828497,9.28562,550.019,550.321,,,,
3.81683,0.000697222,0.0117745,11.1464,550.024,550.321,,,,
3.81697,0.000836111,0.0126908,12.9657,550.024,550.319,,,,
3.81711,0.000975,0.0136335,14.736,550.023,550.319,,,,
3.81726,0.001125,0.0163506,16.6077,550.025,550.324,,,,
3.81741,0.00127778,0.0185309,18.3995,550.025,550.324,,,,
3.81757,0.00143611,0.0205123,20.1928,550.027,550.338,,,,
3.81775,0.00161111,0.0234191,22.0138,550.027,550.326,,,,
3.81794,0.00180833,0.0260668,23.8309,550.033,550.326,,,,
3.81813,0.00199722,0.0288167,25.6745,550.042,550.317,,,,
3.81829,0.00215,0.03043,27.5417,550.042,550.326,,,,
3.81841,0.00227778,0.0318558,29.3719,550.039,550.326,,,,
3.81854,0.0024,0.0328264,31.2532,550.039,550.326,,,,
3.81866,0.00252222,0.0344932,33.1514,550.04,550.329,,,,
3.81877,0.00263333,0.0357142,34.9405,550.04,550.329,,,,
3.81888,0.00274444,0.0364304,36.7792,550.04,550.332,,,,
3.81899,0.00285556,0.0372058,38.6254,550.043,550.332,,,,
3.8191,0.00296389,0.0378734,40.5002,550.043,550.332,,,,
3.8192,0.00306111,0.0387823,42.2768,550.047,550.338,,,,
3.81929,0.00315833,0.0399512,44.1257,550.047,550.338,,,,
3.81939,0.00325556,0.0408357,45.9822,550.047,550.338,,,,
3.81949,0.00335278,0.0419408,47.8886,550.04,550.346,,,,
3.81959,0.00345,0.0428116,49.8356,550.04,550.346,,,,
3.81968,0.00354722,0.0436415,51.7964,550.04,550.323,,,,
3.81978,0.00364444,0.0445731,53.7764,550.038,550.323,,,,
3.81988,0.00374167,0.0456215,55.7554,550.038,550.323,,,,
3.81997,0.00383889,0.0468194,57.7529,550.038,550.332,,,,
3.82007,0.00393333,0.0476424,59.713,550.034,550.332,,,,
3.82016,0.00402778,0.0485638,61.6441,550.034,550.332,,,,
3.82026,0.004125,0.0495256,63.6031,550.034,550.326,,,,
3.82036,0.00422222,0.0505002,65.5867,550.032,550.326,,,,
3.82045,0.00431389,0.0515992,67.4803,550.032,550.326,,,,
3.82055,0.00441111,0.0525162,69.4843,550.032,550.334,,,,
3.82064,0.00450833,0.0534216,71.4449,550.041,550.334,,,,
3.82074,0.00460556,0.0544044,73.3984,550.041,550.334,,,,
3.82084,0.0047,0.0555853,75.3143,550.041,550.338,,,,
3.82093,0.00479722,0.0570099,77.2954,550.034,550.338,,,,
3.82103,0.00489444,0.0584497,79.2179,550.034,550.338,,,,
3.82113,0.00499167,0.0597205,81.1404,550.034,550.333,,,,
3.82122,0.00508889,0.0608652,83.0806,550.036,550.333,,,,
3.82132,0.00518611,0.0619014,84.9948,550.036,550.321,,,,
3.82142,0.00528333,0.0629492,86.8576,550.035,550.321,,,,
3.82152,0.00538056,0.063889,88.7048,550.035,550.321,,,,
3.82161,0.00547778,0.0650922,90.5483,550.035,550.329,,,,
3.82171,0.005575,0.0662289,92.387,550.034,550.329,,,,
3.82181,0.005675,0.067803,94.2134,550.034,550.329,,,,
3.82192,0.00578333,0.0692514,96.124,550.034,550.32,,,,
3.82203,0.00589167,0.0712299,98.0348,550.032,550.32,,,,
3.82214,0.00600278,0.0728953,99.9602,550.032,550.32,,,,
3.82225,0.00611389,0.0752388,101.792,550.032,550.323,,,,
3.82237,0.00623056,0.0777194,103.629,550.032,550.323,,,,
3.82249,0.00635278,0.0805149,105.483,550.032,550.318,,,,
3.82262,0.00648333,0.0839539,107.321,550.02,550.318,,,,
3.82276,0.00662222,0.0871194,109.131,550.02,550.317,,,,
3.82291,0.00677778,0.0914402,111.004,550.017,550.317,,,,
3.82309,0.00695,0.0976309,112.801,550.017,550.318,,,,
3.82328,0.00714722,0.104813,114.591,550.016,550.318,,,,
3.82351,0.00737778,0.113335,116.372,550.019,550.318,,,,
3.82375,0.00761389,0.122096,118.145,550.007,550.316,,,,
3.82401,0.00786944,0.131983,119.917,550.007,550.325,,,,
3.82427,0.00813611,0.142435,121.693,550.01,550.33,,,,
3.82455,0.00841111,0.153189,123.484,550.007,550.307,,,,
3.82484,0.00870556,0.165483,125.283,550.005,550.313,,,,
3.82514,0.00900833,0.178541,127.068,550.008,550.308,,,,
3.82545,0.00931389,0.191257,128.841,550.005,550.309,,,,
3.82577,0.00963056,0.20477,130.619,550.008,550.313,,,,
3.8261,0.00996389,0.21904,132.395,550.007,550.324,,,,
3.82645,0.0103139,0.233888,134.182,550.007,550.324,,,,
3.82681,0.0106722,0.249728,135.938,549.995,550.317,,,,
3.82718,0.0110444,0.266101,137.706,550.004,550.316,,,,
3.82758,0.0114417,0.283553,139.49,550.001,550.312,,,,
3.82799,0.0118583,0.301223,141.263,550.011,550.324,,,,
3.82843,0.0122917,0.319684,143.043,549.999,550.317,,,,
3.82888,0.0127444,0.33947,144.818,550.009,550.31,,,,
3.82936,0.0132194,0.3622,146.587,550.012,550.317,,,,
3.82986,0.0137194,0.387081,148.351,550.014,550.322,,,,
3.83039,0.0142583,0.412075,150.114,550.004,550.324,,,,
3.83096,0.0148194,0.439819,151.884,550.016,550.329,,,,
3.83155,0.0154139,0.469307,153.635,550.006,550.332,,,,
3.83218,0.0160444,0.500308,155.399,550.002,550.331,,,,
3.83286,0.0167278,0.534046,157.165,549.997,550.342,,,,
3.83357,0.0174306,0.571401,158.915,550.005,550.348,,,,
3.83432,0.0181861,0.611351,160.667,550.015,550.344,,,,
3.83513,0.0189944,0.652921,162.423,550.017,550.345,,,,
3.836,0.0198611,0.69577,164.17,550.028,550.347,,,,
3.83693,0.0207944,0.748018,165.926,550.014,550.352,,,,
3.83791,0.0217722,0.802783,167.68,550.011,550.38,,,,
3.83897,0.0228306,0.850045,169.429,550.021,550.371,,,,
3.84003,0.0238944,0.890813,171.191,550.026,550.39,,,,
3.84114,0.025,0.972001,172.943,550.028,550.385,,,,
3.84231,0.0261722,1.05015,174.697,550.015,550.383,,,,
3.84373,0.0275972,1.0981,175.756,550.008,550.398,,,,
3.84444,0.0283056,1.11434,177.517,550.009,550.407,,,,
3.84516,0.0290278,1.16231,179.276,550.002,550.407,,,,
3.84577,0.0296333,1.21206,178.906,550.005,550.399,,,,
3.84704,0.0309028,1.3007,180.664,550.025,550.422,,,,
3.84797,0.0318361,1.31566,182.439,550.015,550.429,,,,
3.84828,0.0321472,1.32434,182.756,550.021,550.421,,,,
3.84869,0.0325583,1.35806,182.393,550.029,550.421,,,,
3.84921,0.0330694,1.39745,184.172,550.019,550.438,,,,
3.84987,0.0337333,1.44011,184.517,550.026,550.434,,,,
3.8508,0.0346611,1.45762,184.839,550.036,550.441,,,,
3.85162,0.0354861,1.50729,186.607,550.027,550.444,,,,
3.85208,0.0359444,1.542,188.38,550.028,550.448,,,,
3.85228,0.0361472,1.56376,186.568,550.024,550.448,,,,
3.85356,0.0374222,1.63909,188.324,550.027,550.458,,,,
3.85439,0.0382556,1.64482,190.074,550.024,550.473,,,,
3.85468,0.0385444,1.64637,191.849,550.031,550.466,,,,
3.85499,0.03885,1.65742,191.436,550.036,550.469,,,,
3.85561,0.039475,1.7103,190.332,550.03,550.474,,,,
3.85634,0.0402056,1.76953,192.105,550.036,550.471,,,,
3.85688,0.0407444,1.8092,192.403,550.041,550.479,,,,
3.85759,0.0414556,1.818,192.014,550.028,550.478,,,,
3.85844,0.0423028,1.8551,193.777,550.031,550.485,,,,
3.85884,0.0427056,1.87832,195.552,550.023,550.493,,,,
3.85932,0.0431889,1.91202,195.807,550.034,550.487,,,,
3.85943,0.0432972,1.92581,193.936,550.034,550.481,,,,
3.86052,0.0443861,1.99542,195.694,550.041,550.492,,,,
3.86119,0.0450528,2.00748,197.452,550.046,550.5,,,,
3.86187,0.0457333,2.02719,197.08,550.044,550.498,,,,
3.86292,0.0467833,2.10908,198.841,550.026,550.512,,,,
3.86364,0.0475083,2.16575,200.602,550.036,550.531,,,,
3.86412,0.0479806,2.19455,200.194,550.037,550.53,,,,
3.86476,0.0486278,2.19725,199.823,550.058,550.525,,,,
3.86536,0.0492222,2.20623,201.59,550.056,550.535,,,,
3.86616,0.050025,2.24858,203.345,550.061,550.531,,,,
3.86705,0.0509111,2.28125,202.994,550.057,550.534,,,,
3.86747,0.0513361,2.31863,201.863,550.05,550.537,,,,
3.8683,0.0521611,2.37282,203.622,550.071,550.543,,,,
3.86919,0.05305,2.39491,205.375,550.054,550.546,,,,
3.87039,0.0542556,2.47383,206.429,550.064,550.534,,,,
3.87144,0.0553056,2.55662,208.187,550.054,550.507,,,,
3.87206,0.0559194,2.60656,209.947,550.021,550.505,,,,
3.87237,0.0562306,2.62121,208.092,550.008,550.501,,,,
3.87358,0.0574472,2.63964,209.143,550.008,550.49,,,,
3.87397,0.0578361,2.65468,210.905,550.002,550.488,,,,
3.87439,0.0582583,2.66829,212.663,550.01,550.486,,,,
3.87478,0.0586444,2.6878,211.574,550.007,550.482,,,,
3.87489,0.05875,2.70025,209.739,550.007,550.482,,,,
3.87612,0.0599833,2.77811,211.497,550.004,550.492,,,,
3.87714,0.061,2.79315,211.854,550.007,550.501,,,,
3.87751,0.0613778,2.79497,213.643,550.002,550.503,,,,
3.8778,0.0616611,2.7972,215.438,550.016,550.498,,,,
3.87818,0.0620472,2.81218,214.319,550.009,550.497,,,,
3.87869,0.0625583,2.85797,213.91,550.006,550.498,,,,
3.87971,0.0635722,2.94168,215.659,549.999,550.508,,,,
3.88073,0.0645972,3.0209,217.419,550.009,550.517,,,,
3.88141,0.0652722,3.05875,217.734,550.013,550.485,,,,
3.88184,0.0657083,3.06254,217.335,550.008,550.471,,,,
3.88276,0.0666278,3.07226,219.098,549.981,550.438,,,,
3.88321,0.0670694,3.08817,220.876,549.971,550.434,,,,
3.88352,0.0673889,3.1068,220.421,549.977,550.429,,,,
3.88358,0.0674444,3.11625,218.424,549.977,550.423,,,,
3.8843,0.0681667,3.1738,218.743,549.961,550.427,,,,
3.88523,0.0690944,3.21256,220.499,549.964,550.42,,,,
3.88608,0.0699444,3.22217,222.258,549.95,550.434,,,,
3.88676,0.0706194,3.23315,223.295,549.949,550.436,,,,
3.88692,0.0707861,3.25029,221.467,549.949,550.437,,,,
3.88791,0.071775,3.33384,223.218,549.958,550.444,,,,
3.88899,0.07285,3.42288,224.971,549.963,550.459,,,,
3.89001,0.0738722,3.49952,226.736,549.962,550.47,,,,
3.89094,0.0748083,3.53671,227.78,549.974,550.443,,,,
3.89167,0.0755389,3.54228,226.693,549.972,550.423,,,,
3.89204,0.0759028,3.54594,228.479,549.962,550.425,,,,
3.89232,0.0761861,3.54934,230.265,549.953,550.412,,,,
3.89254,0.0764056,3.56138,228.268,549.953,550.413,,,,
3.89261,0.0764694,3.57064,226.342,549.957,550.413,,,,
3.8933,0.0771611,3.62006,227.391,549.945,550.404,,,,
3.89415,0.0780167,3.66235,229.143,549.931,550.405,,,,
3.89575,0.0796167,3.69025,230.912,549.901,550.377,,,,
3.89598,0.0798472,3.69275,232.719,549.895,550.364,,,,
3.8963,0.0801639,3.70029,233.05,549.898,550.363,,,,
3.89638,0.0802444,3.71012,231.164,549.898,550.371,,,,
3.89709,0.08095,3.77078,231.504,549.886,550.359,,,,
3.89833,0.0821917,3.87264,233.26,549.878,550.385,,,,
3.89915,0.0830167,3.94238,235.02,549.884,550.388,,,,
3.90064,0.0845056,4.00455,235.372,549.893,550.383,,,,
3.90132,0.0851806,4.00442,237.13,549.906,550.403,,,,
3.90191,0.0857694,4.00815,238.887,549.91,550.394,,,,
3.90216,0.0860278,4.02194,237.627,549.902,550.398,,,,
3.90222,0.0860889,4.03184,235.666,549.902,550.406,,,,
3.90327,0.0871333,4.11741,236.711,549.899,550.39,,,,
3.90463,0.0884972,4.16177,238.464,549.896,550.409,,,,
3.90532,0.0891806,4.16583,240.212,549.906,550.422,,,,
3.90589,0.0897583,4.16757,241.961,549.912,550.427,,,,
3.90621,0.090075,4.17674,241.593,549.922,550.435,,,,
3.90631,0.0901694,4.18759,239.766,549.922,550.435,,,,
3.90777,0.0916389,4.30271,241.512,549.931,550.427,,,,
3.90883,0.0926917,4.39383,243.268,549.917,550.419,,,,
3.91037,0.0942333,4.48295,244.322,549.918,550.433,,,,
3.91138,0.0952444,4.49822,246.076,549.913,550.418,,,,
3.9122,0.0960639,4.50053,247.848,549.919,550.422,,,,
3.91246,0.0963194,4.50778,248.153,549.917,550.422,,,,
3.91251,0.0963694,4.51576,246.19,549.917,550.424,,,,
3.91264,0.0965028,4.53059,244.334,549.926,550.424,,,,
3.91402,0.0978806,4.62982,246.083,549.918,550.418,,,,
3.91479,0.0986583,4.65057,247.844,549.912,550.435,,,,
3.91584,0.0997056,4.65527,249.589,549.913,550.437,,,,
3.91647,0.100331,4.65504,251.357,549.93,550.455,,,,
3.91677,0.100631,4.66544,251.685,549.935,550.451,,,,
3.91683,0.100692,4.67439,249.797,549.935,550.451,,,,
3.91752,0.101381,4.73318,249.421,549.936,550.472,,,,
3.91871,0.102575,4.83253,251.181,549.953,550.485,,,,
3.92055,0.104417,4.97876,252.934,549.969,550.518,,,,
3.92173,0.105594,5.01451,254.686,549.998,550.524,,,,
3.92291,0.106775,5.02513,256.439,550,550.54,,,,
3.92333,0.107192,5.0365,257.475,550.003,550.546,,,,
3.92339,0.10725,5.04533,255.575,550.003,550.546,,,,
3.92349,0.10735,5.05817,253.743,550.013,550.546,,,,
3.92467,0.108533,5.14341,255.496,550.034,550.556,,,,
3.9256,0.109461,5.17437,257.244,550.034,550.578,,,,
3.92675,0.110617,5.18028,258.995,550.053,550.606,,,,
3.92747,0.111339,5.18281,260.762,550.063,550.617,,,,
3.92782,0.111686,5.19278,261.812,550.073,550.622,,,,
3.92788,0.111744,5.20171,259.84,550.066,550.622,,,,
3.92841,0.112269,5.24906,258.658,550.07,550.631,,,,
3.9305,0.114361,5.43438,260.413,550.083,550.653,,,,
3.93137,0.115236,5.50468,262.167,550.103,550.682,,,,
3.93275,0.116611,5.5706,263.919,550.128,550.695,,,,
3.9343,0.118161,5.57965,265.676,550.163,550.708,,,,
3.93457,0.118433,5.5824,267.483,550.161,550.716,,,,
3.93482,0.118689,5.59413,267.032,550.159,550.71,,,,
3.93488,0.118747,5.6037,265.01,550.159,550.71,,,,
3.93561,0.119478,5.66701,264.637,550.171,550.731,,,,
3.93677,0.120639,5.73215,266.385,550.186,550.736,,,,
3.93792,0.121786,5.74821,268.14,550.186,550.76,,,,
3.9388,0.122667,5.75163,269.895,550.188,550.748,,,,
3.93934,0.123203,5.75261,271.677,550.191,550.76,,,,
3.93965,0.123511,5.76699,271.251,550.189,550.751,,,,
3.93971,0.123569,5.77621,269.352,550.189,550.745,,,,
3.94115,0.125017,5.90437,268.935,550.189,550.744,,,,
3.94218,0.126042,5.9882,270.688,550.187,550.754,,,,
3.9435,0.127364,6.09445,272.44,550.188,550.74,,,,
3.94495,0.128817,6.14562,274.187,550.211,550.76,,,,
3.94601,0.129869,6.14808,275.946,550.212,550.758,,,,
3.94666,0.130519,6.14855,277.741,550.208,550.764,,,,
3.94689,0.130753,6.15706,276.572,550.219,550.765,,,,
3.94695,0.130817,6.16618,274.678,550.219,550.765,,,,
3.94751,0.131372,6.21498,274.304,550.221,550.75,,,,
3.94894,0.132806,6.31733,276.049,550.191,550.727,,,,
3.95006,0.133925,6.3517,277.804,550.194,550.717,,,,
3.95104,0.134903,6.35553,279.559,550.188,550.713,,,,
3.9518,0.135661,6.35555,280.631,550.176,550.717,,,,
3.95207,0.135933,6.35861,282.415,550.178,550.724,,,,
3.95223,0.136092,6.37029,280.476,550.178,550.725,,,,
3.95229,0.136158,6.37943,278.598,550.177,550.725,,,,
3.95337,0.137231,6.47084,278.949,550.17,550.716,,,,
3.95449,0.138353,6.56662,280.704,550.172,550.709,,,,
3.95598,0.139844,6.67993,282.452,550.187,550.717,,,,
3.9574,0.141267,6.7362,284.202,550.185,550.707,,,,
3.95861,0.142478,6.74398,285.96,550.178,550.703,,,,
3.95947,0.143333,6.74288,287.758,550.178,550.698,,,,
3.95974,0.143603,6.75299,287.333,550.179,550.701,,,,
3.95979,0.143658,6.7625,285.209,550.178,550.701,,,,
3.96025,0.144114,6.80507,283.997,550.176,550.697,,,,
3.9618,0.145664,6.93225,285.749,550.168,550.677,,,,
3.96293,0.146794,6.98237,287.502,550.166,550.677,,,,
3.96414,0.148003,6.9933,289.255,550.144,550.665,,,,
3.96524,0.149106,6.99445,290.315,550.151,550.649,,,,
3.96548,0.149347,6.9957,292.114,550.143,550.653,,,,
3.96585,0.149711,7.00703,292.426,550.149,550.663,,,,
3.96591,0.149775,7.01639,290.451,550.146,550.663,,,,
3.96604,0.149903,7.03173,288.588,550.146,550.663,,,,
3.96744,0.151306,7.14676,290.337,550.14,550.651,,,,
3.96903,0.152892,7.27737,292.089,550.132,550.644,,,,
3.97043,0.154297,7.36993,293.845,550.159,550.63,,,,
3.97187,0.155736,7.39354,295.597,550.162,550.619,,,,
3.97302,0.156883,7.39525,296.641,550.156,550.606,,,,
3.97331,0.157169,7.39835,298.42,550.154,550.61,,,,
3.97361,0.157472,7.40959,298.729,550.164,550.609,,,,
3.97367,0.157531,7.4188,296.801,550.164,550.609,,,,
3.97374,0.157603,7.43015,294.86,550.157,550.609,,,,
3.97478,0.158644,7.5198,295.191,550.16,550.594,,,,
3.97613,0.159997,7.61613,296.942,550.161,550.586,,,,
3.97746,0.161319,7.65205,298.69,550.157,550.573,,,,
3.97853,0.162392,7.65599,300.455,550.147,550.562,,,,
3.97919,0.163058,7.65766,300.804,550.146,550.557,,,,
3.97954,0.163403,7.65967,302.59,550.138,550.555,,,,
3.97991,0.163775,7.6696,303.642,550.156,550.553,,,,
3.97999,0.16385,7.67975,301.661,550.156,550.553,,,,
3.98007,0.163939,7.69174,299.717,550.14,550.549,,,,
3.9816,0.165467,7.82236,300.766,550.136,550.542,,,,
3.98307,0.166936,7.94646,302.52,550.13,550.532,,,,
3.98441,0.168275,8.0413,304.271,550.138,550.535,,,,
3.98603,0.169892,8.07994,306.024,550.153,550.524,,,,
3.98691,0.170778,8.08429,307.775,550.147,550.521,,,,
3.98768,0.171547,8.08834,308.843,550.154,550.513,,,,
3.98803,0.171894,8.09869,309.123,550.156,550.508,,,,
3.98809,0.171953,8.10766,307.222,550.156,550.499,,,,
3.98817,0.172031,8.11847,305.38,550.156,550.499,,,,
3.98904,0.172908,8.19161,305.713,550.153,550.485,,,,
3.99045,0.174317,8.2982,307.468,550.142,550.479,,,,
3.99181,0.175678,8.3478,309.221,550.147,550.461,,,,
3.99292,0.176789,8.35561,310.974,550.141,550.465,,,,
3.99387,0.177731,8.36092,312.028,550.128,550.44,,,,
3.9943,0.178161,8.36166,313.109,550.123,550.442,,,,
3.99459,0.17845,8.36394,314.896,550.125,550.443,,,,
3.99483,0.178697,8.37706,313.684,550.12,550.44,,,,
3.99489,0.178756,8.38647,311.816,550.12,550.44,,,,
3.99502,0.178883,8.40193,310.018,550.12,550.435,,,,
3.99678,0.180644,8.54673,311.772,550.119,550.408,,,,
3.9982,0.182067,8.66299,313.524,550.117,550.402,,,,
3.99979,0.18365,8.77066,315.277,550.117,550.388,,,,
4.00114,0.185003,8.80244,317.025,550.128,550.387,,,,
4.00235,0.186211,8.81199,318.782,550.13,550.369,,,,
4.00308,0.186942,8.8113,319.143,550.125,550.351,,,,
4.00456,0.188419,8.85316,318.747,550.131,550.341,,,,
4.00492,0.188786,9.20351,319.043,550.126,550.339,,,,
4.05537,0.239239,9.32309,320.002,550.063,550.164,,,,
4.13871,0.322572,9.33092,320.006,550.03,550.241,,,,
4.22204,0.405906,9.33083,319.999,549.961,550.29,,,,
4.30537,0.489239,9.3311,320.008,550.012,550.108,,,,
4.38871,0.572572,9.33786,320.003,549.953,550.115,,,,
4.47204,0.655906,9.34955,320.007,549.857,550.277,,,,
4.55537,0.739239,9.34249,320.005,549.933,549.973,,,,
4.63871,0.822572,9.34445,320.008,549.966,549.953,,,,
4.72204,0.905906,9.35421,320.011,549.818,550.21,,,,
4.80537,0.989239,9.35171,319.998,549.876,549.905,,,,
4.88871,1.07257,9.35292,320.003,549.95,549.912,,,,
4.97204,1.15591,9.35514,320.001,549.851,550.257,,,,
5.32204,1.50591,9.35824,319.992,549.921,549.9,,,,
5.73871,1.92257,9.36259,320.007,549.896,550.163,,,,
6.15537,2.33924,9.36625,320,549.888,549.871,,,,
6.57204,2.75591,9.37049,320,549.805,550.074,,,,
6.98871,3.17257,9.36982,319.994,549.881,549.896,,,,
7.40537,3.58924,9.38472,320.001,549.761,550.147,,,,
7.82204,4.00591,9.38037,319.993,549.824,549.777,,,,
8.23871,4.42257,9.38787,320,549.871,550.159,,,,
8.65537,4.83924,9.38057,319.998,549.959,549.981,,,,
9.07204,5.25591,9.38667,320.001,549.992,550.232,,,,
9.48871,5.67257,9.38639,319.998,549.904,549.923,,,,
9.90537,6.08924,9.38505,320,549.721,549.927,,,,
10.322,6.50591,9.39355,320.005,549.908,549.895,,,,
10.7387,6.92257,9.39713,320,549.806,549.888,,,,
11.1554,7.33924,9.39977,319.993,549.939,549.925,,,,
11.572,7.75591,9.39377,320.004,549.908,549.887,,,,
11.9887,8.17257,9.40379,319.999,549.936,550.003,,,,
12.4054,8.58924,9.39924,319.997,549.954,549.824,,,,
12.822,9.00591,9.39849,320.002,549.831,549.853,,,,
13.2387,9.42257,9.40344,320.008,549.999,550.062,,,,
13.6554,9.83924,9.40462,319.999,549.973,549.907,,,,
14.072,10.2559,9.41095,319.995,549.881,549.811,,,,
14.4887,10.6726,9.41867,320.002,549.889,549.998,,,,
14.9054,11.0892,9.41298,320,549.897,549.863,,,,
15.322,11.5059,9.41453,319.998,549.982,549.951,,,,
15.7387,11.9226,9.41111,319.999,549.902,549.936,,,,
16.1554,12.3392,9.41587,319.999,550.024,549.926,,,,
16.572,12.7559,9.41664,320.003,549.79,549.83,,,,
16.9887,13.1726,9.41422,320.007,549.901,549.875,,,,
17.4054,13.5892,9.41486,319.996,549.925,549.833,,,,
17.822,14.0059,9.41798,320.008,549.987,550.049,,,,
18.2387,14.4226,9.42446,320.004,549.93,549.985,,,,
18.6554,14.8392,9.42136,320.006,549.934,549.864,,,,
19.072,15.2559,9.43031,320.01,549.873,549.954,,,,
19.4887,15.6726,9.42728,320.01,549.896,549.972,,,,
19.9054,16.0892,9.42609,320.001,549.975,549.871,,,,
20.322,16.5059,9.43274,319.998,549.926,549.855,,,,
20.7387,16.9226,9.42963,320.006,549.813,549.879,,,,
21.1554,17.3392,9.42786,320,549.92,549.968,,,,
21.572,17.7559,9.42895,320.003,549.895,549.795,,,,
21.9887,18.1726,9.43081,320.011,549.894,549.908,,,,
22.4054,18.5892,9.4301,320.001,549.969,549.987,,,,
22.822,19.0059,9.42925,320.006,549.804,549.813,,,,
23.2387,19.4226,9.43082,320.009,549.994,549.888,,,,
23.6554,19.8392,9.42962,320.008,549.936,549.898,,,,
24.072,20.2559,9.44323,320,549.897,549.943,,,,
24.4887,20.6726,9.43573,320.004,549.891,549.971,,,,
24.9054,21.0892,9.43773,320.007,549.942,549.87,,,,
25.322,21.5059,9.43638,320.001,549.894,549.805,,,,
25.7387,21.9226,9.4423,320.001,549.874,549.974,,,,
26.1554,22.3392,9.44459,319.999,549.912,550.004,,,,
26.572,22.7559,9.43856,320,549.906,549.801,,,,
26.9887,23.1726,9.43533,319.997,549.845,549.906,,,,
27.4054,23.5892,9.44816,320.001,549.889,549.956,,,,
27.822,24.0059,9.44746,320.007,549.922,549.894,,,,
28.2387,24.4226,9.44457,320.004,550.011,549.945,,,,
28.6554,24.8392,9.45196,320.001,549.867,549.999,,,,
29.072,25.2559,9.44515,320.003,549.902,549.967,,,,
29.4887,25.6726,9.44483,320.002,549.921,549.842,,,,
29.9054,26.0892,9.45059,320,549.932,549.907,,,,
30.322,26.5059,9.45247,320,549.936,549.981,,,,
30.7387,26.9226,9.45095,319.999,549.836,549.858,,,,
31.1554,27.3392,9.451,320.002,549.879,549.761,,,,
31.572,27.7559,9.45526,320.002,549.937,549.966,,,,
31.9887,28.1726,9.45225,319.999,549.883,549.918,,,,
32.4054,28.5892,9.45015,320.004,549.937,549.82,,,,
32.822,29.0059,9.44957,320.005,549.885,549.904,,,,
33.2387,29.4226,9.4543,320.004,549.939,549.997,,,,
33.6554,29.8392,9.45288,320.001,549.987,549.912,,,,
34.072,30.2559,9.4559,320.004,550.014,549.939,,,,
34.4887,30.6726,9.45977,319.998,549.884,549.92,,,,
34.9054,31.0892,9.4554,320,549.913,550.005,,,,
35.322,31.5059,9.45194,320.004,549.877,549.772,,,,
35.7387,31.9226,9.45763,319.997,549.924,549.843,,,,
36.1554,32.3392,9.44992,319.997,549.799,549.919,,,,
36.572,32.7559,9.45555,320.004,549.878,549.894,,,,
36.9887,33.1726,9.45922,320.007,550.005,550.048,,,,
37.4054,33.5892,9.45581,319.996,549.979,549.896,,,,
37.822,34.0059,9.46195,320.004,549.867,549.926,,,,
38.2387,34.4226,9.46457,320,550.005,550.062,,,,
38.6554,34.8392,9.45862,319.999,549.9,549.881,,,,
39.072,35.2559,9.45763,320.004,549.893,549.8,,,,
39.4887,35.6726,9.4604,320,549.913,549.868,,,,
39.9054,36.0892,9.46829,320.004,549.926,549.957,,,,
40.322,36.5059,9.46197,320.001,549.898,549.997,,,,
40.7387,36.9226,9.46495,319.997,549.987,549.873,,,,
41.1554,37.3392,9.46607,320.002,549.798,549.918,,,,
41.572,37.7559,9.4626,320.001,549.852,549.935,,,,
41.9887,38.1726,9.46446,320.002,549.738,549.844,,,,
42.4054,38.5892,9.46523,319.995,549.966,549.884,,,,
42.822,39.0059,9.4588,319.997,549.937,549.924,,,,
43.2387,39.4226,9.47044,320.007,549.91,549.947,,,,
43.6554,39.8392,9.46615,320.001,549.956,549.83,,,,
44.072,40.2559,9.46721,320.003,550.026,549.898,,,,
44.4887,40.6726,9.46457,319.999,549.865,549.883,,,,
44.9054,41.0892,9.47125,320.003,549.873,549.912,,,,
45.322,41.5059,9.46949,320.003,549.918,549.961,,,,
45.7387,41.9226,9.46703,320.002,549.931,549.817,,,,
46.1554,42.3392,9.47187,320.01,549.962,550.005,,,,
46.572,42.7559,9.47331,319.993,549.918,549.986,,,,
46.9887,43.1726,9.47158,320.002,549.872,549.984,,,,
47.4054,43.5892,9.47355,320.007,549.913,549.847,,,,
47.822,44.0059,9.47585,319.999,549.888,549.794,,,,
48.2387,44.4226,9.47776,320.005,549.754,549.818,,,,
48.6554,44.8392,9.47521,319.999,549.895,549.945,,,,
49.072,45.2559,9.47401,320.004,549.938,549.86,,,,
49.4887,45.6726,9.4745,320.001,549.992,549.922,,,,
49.9054,46.0892,9.4799,320.011,549.905,549.962,,,,
50.322,46.5059,9.48065,319.995,549.883,549.912,,,,
50.7387,46.9226,9.47872,319.998,549.858,549.763,,,,
51.1554,47.3392,9.47593,320.013,549.975,549.862,,,,
51.572,47.7559,9.4834,320.002,549.975,550.033,,,,
51.9887,48.1726,9.478,320.003,549.969,550.045,,,,
52.4054,48.5892,9.48373,320,549.964,549.956,,,,
52.822,49.0059,9.47651,320.005,549.936,549.828,,,,
53.2387,49.4226,9.48325,320.002,549.866,549.946,,,,
53.6554,49.8392,9.48303,320.006,549.925,550.005,,,,
54.072,50.2559,9.47855,320.006,549.882,549.816,,,,
54.4887,50.6726,9.47619,320.003,549.938,549.837,,,,
54.9054,51.0892,9.48993,320.004,549.84,549.914,,,,
55.322,51.5059,9.48511,320.006,549.902,549.991,,,,
55.7387,51.9226,9.47901,319.992,550.015,549.895,,,,
56.1554,52.3392,9.48434,320.001,549.919,549.917,,,,
56.572,52.7559,9.48231,320.005,549.973,550.019,,,,
56.9887,53.1726,9.4834,320.003,549.996,549.889,,,,
57.4054,53.5892,9.48169,319.994,549.889,549.82,,,,
57.822,54.0059,9.48318,320.004,549.833,549.905,,,,
58.2387,54.4226,9.48864,320.004,549.894,549.846,,,,
58.6554,54.8392,9.47905,320.01,549.884,549.812,,,,
59.072,55.2559,9.48244,320.004,549.902,549.885,,,,
59.4887,55.6726,9.48874,319.994,549.853,549.875,,,,
59.9054,56.0892,9.4873,320.003,549.903,549.978,,,,
60.322,56.5059,9.48588,319.993,549.982,549.864,,,,
60.7387,56.9226,9.48556,320.002,549.951,549.913,,,,
61.1554,57.3392,9.48994,320.012,549.942,550.077,,,,
61.572,57.7559,9.49005,320,549.832,549.91,,,,
61.9887,58.1726,9.48925,320.007,550.021,549.919,,,,
62.4054,58.5892,9.49404,320.005,549.843,549.901,,,,
62.822,59.0059,9.48185,320.008,549.857,549.945,,,,
63.2387,59.4226,9.49135,320.009,549.955,549.998,,,,
63.6554,59.8392,9.48934,320.007,549.933,549.831,,,,
64.072,60.2559,9.49216,319.997,549.775,549.944,,,,
64.4887,60.6726,9.48947,320.003,549.887,549.964,,,,
64.9054,61.0892,9.49305,320.007,549.924,549.851,,,,
65.322,61.5059,9.48796,319.999,549.797,549.77,,,,
65.7387,61.9226,9.5036,320.005,549.933,549.96,,,,
66.1554,62.3392,9.4901,319.999,549.874,549.991,,,,
66.572,62.7559,9.49174,319.993,549.899,549.805,,,,
66.9887,63.1726,9.49481,320.011,549.898,549.926,,,,
67.4054,63.5892,9.49955,320.007,549.917,549.966,,,,
67.822,64.0059,9.49798,319.991,549.922,549.974,,,,
68.2387,64.4226,9.49438,320.01,549.947,549.923,,,,
68.6554,64.8392,9.49694,319.997,549.981,549.958,,,,
69.072,65.2559,9.49583,320.006,549.868,549.879,,,,
69.4887,65.6726,9.49346,319.999,549.883,549.936,,,,
69.9054,66.0892,9.49653,320.001,549.923,549.808,,,,
70.322,66.5059,9.49516,320.002,549.852,549.909,,,,
70.7387,66.9226,9.49957,320.001,549.893,549.78,,,,
71.1554,67.3392,9.50215,319.995,549.905,549.882,,,,
71.572,67.7559,9.49685,320.001,549.829,549.834,,,,
71.9887,68.1726,9.50357,320.008,549.91,549.959,,,,
72.4054,68.5892,9.49941,320.011,549.927,549.846,,,,
72.822,69.0059,9.5028,320.002,549.98,549.862,,,,
73.2387,69.4226,9.50037,320.01,549.915,549.907,,,,
73.6554,69.8392,9.50407,320.005,549.98,549.94,,,,
74.072,70.2559,9.50508,320.002,549.911,549.929,,,,
74.4887,70.6726,9.50047,320.006,549.855,549.943,,,,
74.9054,71.0892,9.49882,320.003,549.963,549.88,,,,
75.322,71.5059,9.50115,320.011,549.899,550.029,,,,
75.7387,71.9226,9.50085,320.004,549.972,549.917,,,,
76.1554,72.3392,9.49974,320.005,549.69,549.806,,,,
76.572,72.7559,9.50374,320,549.938,549.877,,,,
76.9887,73.1726,9.50468,320.002,549.781,549.844,,,,
77.4054,73.5892,9.50338,320,549.994,549.898,,,,
77.822,74.0059,9.50781,320.004,549.753,549.887,,,,
78.2387,74.4226,9.50146,320.004,549.887,549.824,,,,
78.6554,74.8392,9.50438,320,549.941,549.946,,,,
79.072,75.2559,9.50416,320.007,549.883,549.933,,,,
79.4887,75.6726,9.50482,320.001,549.91,549.941,,,,
79.9054,76.0892,9.50434,319.998,549.949,549.832,,,,
80.322,76.5059,9.50156,320.007,549.901,550.027,,,,
80.7387,76.9226,9.50719,320.002,550.019,549.959,,,,
81.1554,77.3392,9.50972,320.011,549.867,549.871,,,,
81.572,77.7559,9.5099,320.002,549.866,549.946,,,,
81.9887,78.1726,9.51324,320.001,549.927,550.018,,,,
82.4054,78.5892,9.50943,320,549.849,549.874,,,,
82.822,79.0059,9.50986,319.997,550.01,549.905,,,,
83.2387,79.4226,9.51235,320.002,549.883,549.994,,,,
83.6554,79.8392,9.50553,320.009,549.663,549.766,,,,
84.072,80.2559,9.51071,320.001,549.844,549.9,,,,
84.4887,80.6726,9.50624,320.001,550.002,549.935,,,,
84.9054,81.0892,9.51178,319.999,550.024,549.916,,,,
85.322,81.5059,9.50997,320.005,549.985,549.942,,,,
85.7387,81.9226,9.50922,320.002,549.833,549.929,,,,
86.1554,82.3392,9.51825,320.006,549.901,549.97,,,,
86.572,82.7559,9.5078,319.999,549.86,549.93,,,,
86.9887,83.1726,9.50968,319.995,549.913,549.999,,,,
87.4054,83.5892,9.51092,320.003,549.991,549.944,,,,
87.822,84.0059,9.51254,319.999,549.951,549.833,,,,
88.2387,84.4226,9.50786,320.007,549.828,549.835,,,,
88.6554,84.8392,9.51956,319.997,549.832,549.894,,,,
89.072,85.2559,9.5158,320.005,549.884,549.915,,,,
89.4887,85.6726,9.51457,319.995,549.924,550.008,,,,
89.9054,86.0892,9.51336,320.008,549.93,549.996,,,,
90.322,86.5059,9.51264,320,549.992,549.938,,,,
90.7387,86.9226,9.51564,320.002,549.925,549.832,,,,
91.1554,87.3392,9.51538,319.999,549.908,549.925,,,,
91.572,87.7559,9.52574,320.001,549.903,549.952,,,,
91.9887,88.1726,9.5139,319.999,549.88,549.895,,,,
92.4054,88.5892,9.51557,319.995,549.846,549.87,,,,
92.822,89.0059,9.51684,320.007,549.897,549.817,,,,
93.2387,89.4226,9.51382,320.004,550.01,550.021,,,,
93.6554,89.8392,9.51682,320.003,549.794,549.854,,,,
94.072,90.2559,9.51351,320.001,549.9,549.785,,,,
94.4887,90.6726,9.52284,319.998,550.017,550.078,,,,
94.9054,91.0892,9.51684,319.998,549.941,549.848,,,,
95.322,91.5059,9.51522,320.001,549.75,549.739,,,,
95.7387,91.9226,9.51382,319.997,549.862,549.814,,,,
96.1554,92.3392,9.51033,320.003,549.861,549.927,,,,
96.572,92.7559,9.509,320.007,549.963,549.907,,,,
96.9887,93.1726,9.51029,320.005,549.86,549.823,,,,
97.4054,93.5892,9.51115,320.002,549.877,549.882,,,,
97.822,94.0059,9.5096,319.998,549.891,549.85,,,,
98.2387,94.4226,9.50814,320.008,549.954,549.858,,,,
98.6554,94.8392,9.51398,320.006,549.964,550.002,,,,
99.072,95.2559,9.51039,320.014,549.991,549.874,,,,
99.4887,95.6726,9.51332,319.997,549.882,549.973,,,,
99.9054,96.0892,9.5102,320.003,549.978,549.922,,,,
100.322,96.5059,9.51334,319.999,549.971,549.9,,,,
100.739,96.9226,9.5153,320.006,549.962,550.076,,,,
101.155,97.3392,9.51165,320.003,549.983,549.907,,,,
101.572,97.7559,9.51538,320.001,549.961,549.953,,,,
101.989,98.1726,9.51674,320.012,549.863,549.892,,,,
102.405,98.5892,9.516,320.006,549.91,549.874,,,,
102.822,99.0059,9.51065,319.998,549.894,549.867,,,,
103.239,99.4226,9.51573,320.005,549.879,549.838,,,,
103.655,99.8392,9.51427,320.005,549.901,549.955,,,,
104.072,100.256,9.51778,320.004,550.02,549.965,,,,
104.489,100.673,9.52402,320.006,549.977,550.123,,,,
104.905,101.089,9.51953,319.993,549.885,549.827,,,,
105.322,101.506,9.5234,319.999,549.94,549.985,,,,
105.739,101.923,9.51215,320.003,549.972,550.061,,,,
106.155,102.339,9.52026,320,549.955,549.875,,,,
106.572,102.756,9.52552,319.997,549.87,549.961,,,,
106.989,103.173,9.51873,320.007,549.887,549.936,,,,
107.405,103.589,9.51841,320.007,549.867,549.774,,,,
107.822,104.006,9.51202,320.007,549.828,549.821,,,,
108.239,104.423,9.52243,320.009,549.888,549.946,,,,
108.655,104.839,9.52402,320.003,550.012,550.053,,,,
109.072,105.256,9.51914,320.004,550.001,549.921,,,,
109.489,105.673,9.52045,320.001,549.987,550.014,,,,
109.905,106.089,9.5276,320.001,549.756,549.849,,,,
110.322,106.506,9.51774,320.006,549.828,549.91,,,,
110.739,106.923,9.52593,319.994,549.998,549.911,,,,
111.155,107.339,9.52819,320.002,549.892,549.946,,,,
111.572,107.756,9.52498,320.001,549.911,549.971,,,,
111.989,108.173,9.52903,320.001,549.923,550.012,,,,
112.405,108.589,9.52544,320.004,549.979,549.917,,,,
112.822,109.006,9.5236,320,549.926,549.876,,,,
113.239,109.423,9.52535,319.997,549.852,549.949,,,,
113.655,109.839,9.52791,320.004,549.824,549.909,,,,
114.072,110.256,9.52404,320.002,549.979,549.915,,,,
114.489,110.673,9.52233,320,549.923,549.908,,,,
114.905,111.089,9.53442,320.005,549.912,549.96,,,,
115.322,111.506,9.52525,319.998,549.897,549.974,,,,
115.739,111.923,9.52723,320.004,549.751,549.781,,,,
116.155,112.339,9.52705,320.006,549.83,549.778,,,,
116.572,112.756,9.53579,319.999,549.95,549.999,,,,
116.989,113.173,9.52749,319.998,549.919,549.842,,,,
117.405,113.589,9.52896,320.003,549.923,549.878,,,,
117.822,114.006,9.53088,320.004,549.876,549.865,,,,
118.239,114.423,9.52939,320.011,549.981,549.955,,,,
118.655,114.839,9.52959,320.008,549.96,549.882,,,,
119.072,115.256,9.52907,319.998,549.855,549.891,,,,
119.489,115.673,9.53141,320.005,549.962,549.949,,,,
119.905,116.089,9.53243,319.995,550,550.004,,,,
120.322,116.506,9.53812,320,549.804,549.948,,,,
120.739,116.923,9.53088,320.004,549.938,549.882,,,,
121.155,117.339,9.52746,320.004,549.908,549.814,,,,
121.572,117.756,9.53555,320,550.013,549.981,,,,
121.989,118.173,9.52869,320.003,549.907,549.992,,,,
122.405,118.589,9.53399,320.004,549.829,549.922,,,,
122.822,119.006,9.52569,320,549.875,549.935,,,,
123.239,119.423,9.52999,320.007,549.817,549.772,,,,
123.655,119.839,9.52689,320.003,549.876,549.76,,,,
124.072,120.256,9.53029,320.004,549.979,549.88,,,,
124.489,120.673,9.52951,319.989,549.934,549.993,,,,
124.905,121.089,9.53115,320.007,549.84,549.95,,,,
125.322,121.506,9.52808,319.998,549.947,549.888,,,,
125.739,121.923,9.53066,319.999,550,549.894,,,,
126.155,122.339,9.52878,319.999,549.925,549.851,,,,
126.572,122.756,9.53992,319.995,549.908,549.931,,,,
126.989,123.173,9.52645,320.005,549.791,549.942,,,,
127.405,123.589,9.53724,320.003,549.918,550.082,,,,
127.822,124.006,9.53938,320.002,549.772,549.851,,,,
128.239,124.423,9.53146,320.007,549.971,549.927,,,,
128.655,124.839,9.53589,319.999,549.926,550.021,,,,
129.072,125.256,9.53441,320.003,550.043,550.022,,,,
129.489,125.673,9.5323,320.003,549.94,549.924,,,,
129.905,126.089,9.54146,320.009,549.783,549.897,,,,
130.322,126.506,9.53293,320.013,549.929,549.864,,,,
130.739,126.923,9.53969,320.002,549.653,549.744,,,,
131.155,127.339,9.53891,319.997,549.975,550.016,,,,
131.572,127.756,9.53649,320.001,549.995,549.918,,,,
131.989,128.173,9.53703,320.001,549.782,549.887,,,,
132.405,128.589,9.53615,320.006,549.936,549.993,,,,
132.822,129.006,9.5407,320.005,549.932,549.965,,,,
133.239,129.423,9.54214,320,549.988,549.966,,,,
133.655,129.839,9.5347,320.01,549.94,549.868,,,,
134.072,130.256,9.53917,320.007,549.895,549.805,,,,
134.489,130.673,9.5368,320.009,549.845,549.881,,,,
134.905,131.089,9.54813,320.001,549.852,549.852,,,,
135.322,131.506,9.5396,320.007,549.87,549.902,,,,
135.739,131.923,9.54115,320,549.956,549.99,,,,
136.155,132.339,9.54219,320.005,549.945,549.899,,,,
136.572,132.756,9.53858,320.003,549.945,549.862,,,,
136.989,133.173,9.53789,320.007,549.961,549.873,,,,
137.405,133.589,9.5376,320.005,549.953,549.881,,,,
137.822,134.006,9.53999,320.014,549.953,549.976,,,,
138.239,134.423,9.53794,320.001,549.947,550.004,,,,
138.655,134.839,9.54443,320.006,549.931,550.002,,,,
139.072,135.256,9.54436,320.007,549.855,549.946,,,,
139.489,135.673,9.54301,320.001,549.894,549.97,,,,
139.905,136.089,9.54034,319.997,549.856,549.828,,,,
140.322,136.506,9.54006,319.998,549.874,549.796,,,,
140.739,136.923,9.54063,319.999,549.984,549.873,,,,
141.155,137.339,9.54245,320.006,549.781,549.808,,,,
141.572,137.756,9.54492,320.003,550.051,550.068,,,,
141.989,138.173,9.54211,320.003,549.959,550.03,,,,
142.405,138.589,9.54877,320.006,549.816,549.922,,,,
142.822,139.006,9.53806,320.004,549.912,549.811,,,,
143.239,139.423,9.54207,319.994,549.747,549.78,,,,
143.655,139.839,9.54233,320.007,550.022,549.952,,,,
144.072,140.256,9.53861,320.005,549.956,549.979,,,,
144.489,140.673,9.54545,320.005,549.905,549.901,,,,
144.905,141.089,9.54648,320.007,549.914,549.849,,,,
145.322,141.506,9.54934,320,549.843,549.932,,,,
145.739,141.923,9.54057,320.007,549.945,549.857,,,,
146.155,142.339,9.53967,320.006,549.902,550.003,,,,
146.572,142.756,9.54529,320.006,549.942,549.876,,,,
146.989,143.173,9.55404,320.013,549.891,549.971,,,,
147.405,143.589,9.54689,320.007,549.985,549.966,,,,
147.822,144.006,9.54256,320.003,549.891,549.885,,,,
148.239,144.423,9.54724,319.997,549.875,550.005,,,,
148.655,144.839,9.5461,320.004,549.986,549.911,,,,
149.072,145.256,9.5474,320.003,549.864,549.999,,,,
149.489,145.673,9.54382,320.004,549.798,549.733,,,,
149.905,146.089,9.54278,320.004,549.83,549.888,,,,
150.322,146.506,9.54639,320.012,549.923,549.975,,,,
150.739,146.923,9.54408,320.001,549.885,549.777,,,,
151.155,147.339,9.55283,320.004,549.855,549.962,,,,
151.572,147.756,9.5493,320.009,550.009,549.917,,,,
151.989,148.173,9.55211,320,549.846,549.907,,,,
152.405,148.589,9.54909,320.008,549.981,549.893,,,,
152.822,149.006,9.54924,320.001,549.865,549.897,,,,
153.239,149.423,9.54701,320.002,550.05,550.048,,,,
153.655,149.839,9.5428,320.004,549.942,549.958,,,,
154.072,150.256,9.55275,319.996,549.854,549.948,,,,
154.489,150.673,9.55479,320,549.828,549.801,,,,
154.905,151.089,9.54653,320.007,549.871,549.936,,,,
155.322,151.506,9.54843,319.995,550.075,550.02,,,,
155.739,151.923,9.54195,320.003,549.863,549.931,,,,
156.155,152.339,9.54844,320.004,549.804,549.857,,,,
156.572,152.756,9.54497,320.003,549.949,549.92,,,,
156.989,153.173,9.54936,320.006,549.891,549.972,,,,
157.405,153.589,9.55309,320.006,549.986,549.864,,,,
157.822,154.006,9.55683,319.996,549.848,549.875,,,,
158.239,154.423,9.54515,320.009,549.968,549.877,,,,
158.655,154.839,9.55501,320.003,549.906,549.96,,,,
159.072,155.256,9.5536,320.009,549.922,549.82,,,,
159.489,155.673,9.55418,320.014,549.863,549.931,,,,
159.905,156.089,9.55042,320.005,550.004,549.926,,,,
160.322,156.506,9.55424,319.992,549.97,550.014,,,,
160.739,156.923,9.55413,320.004,549.973,549.915,,,,
161.155,157.339,9.55331,320.003,549.906,550.006,,,,
161.572,157.756,9.55375,319.998,550.008,549.976,,,,
161.989,158.173,9.55159,320.007,549.854,549.87,,,,
162.405,158.589,9.55478,320.003,549.852,549.951,,,,
162.822,159.006,9.55397,319.999,549.956,549.875,,,,
163.239,159.423,9.56044,320.003,549.817,549.875,,,,
163.655,159.839,9.55592,320.004,549.873,549.82,,,,
164.072,160.256,9.56138,320.008,549.788,549.826,,,,
164.489,160.673,9.55582,320.004,549.885,549.903,,,,
164.905,161.089,9.55338,320,549.961,549.938,,,,
165.322,161.506,9.55855,320.001,549.946,549.987,,,,
165.739,161.923,9.55596,320.008,549.981,549.888,,,,
166.155,162.339,9.55786,320.002,549.844,549.916,,,,
166.572,162.756,9.5546,319.992,549.837,549.763,,,,
166.989,163.173,9.55977,320.01,549.836,549.913,,,,
167.405,163.589,9.55749,320.003,550.033,549.944,,,,
167.822,164.006,9.56896,320.005,549.901,549.973,,,,
168.239,164.423,9.55804,319.999,549.97,549.909,,,,
168.655,164.839,9.56291,320.007,549.907,549.982,,,,
169.072,165.256,9.55698,319.997,549.917,549.875,,,,
169.489,165.673,9.56179,320.003,549.78,549.881,,,,
169.905,166.089,9.55758,319.996,549.989,549.912,,,,
170.322,166.506,9.5668,319.998,549.939,549.921,,,,
170.739,166.923,9.55298,320.005,549.854,549.946,,,,
171.155,167.339,9.55548,320.009,549.906,549.928,,,,
171.572,167.756,9.55584,320.009,549.941,549.84,,,,
171.989,168.173,9.55437,320.002,549.991,549.911,,,,
172.405,168.589,9.55863,320.002,549.859,549.963,,,,
172.822,169.006,9.55663,320,549.861,549.946,,,,
173.239,169.423,9.55743,320.004,549.943,549.931,,,,
173.655,169.839,9.55632,320.007,549.935,549.873,,,,
174.072,170.256,9.56049,320.01,549.977,549.927,,,,
174.489,170.673,9.5586,320.004,549.923,549.901,,,,
174.905,171.089,9.55235,320.006,549.86,549.759,,,,
175.322,171.506,9.55932,319.996,549.978,550.044,,,,
175.739,171.923,9.55697,320.002,550.034,550.077,,,,
176.155,172.339,9.55388,319.997,550.045,550.009,,,,
176.572,172.756,9.5608,320.005,549.916,549.966,,,,
176.989,173.173,9.56695,320.001,549.975,550.04,,,,
177.405,173.589,9.55818,319.998,549.851,549.801,,,,
177.822,174.006,9.55205,320.005,549.818,549.847,,,,
178.239,174.423,9.55833,320.006,549.856,549.909,,,,
178.655,174.839,9.55795,320.003,549.913,549.858,,,,
179.072,175.256,9.55603,319.999,549.94,549.824,,,,
179.489,175.673,9.55894,320.004,549.993,549.999,,,,
179.905,176.089,9.56227,320.005,549.976,550.005,,,,
180.322,176.506,9.56145,320.008,549.958,549.962,,,,
180.739,176.923,9.55915,320.002,549.981,549.867,,,,
181.155,177.339,9.55779,320.001,549.698,549.756,,,,
181.572,177.756,9.56803,320.001,549.913,549.999,,,,
181.989,178.173,9.55568,319.999,549.938,550.019,,,,
182.405,178.589,9.56468,319.999,549.895,549.952,,,,
182.822,179.006,9.56901,320.001,549.854,549.93,,,,
183.239,179.423,9.56002,320.007,549.93,549.853,,,,
183.655,179.839,9.55624,320.012,549.992,549.878,,,,
184.072,180.256,9.5558,320.009,549.995,549.916,,,,
184.489,180.673,9.5637,319.996,549.846,549.931,,,,
184.905,181.089,9.56915,320.003,549.891,549.974,,,,
185.322,181.506,9.5617,320.002,549.875,549.959,,,,
185.739,181.923,9.56299,320.003,549.94,549.87,,,,
186.155,182.339,9.56173,320.002,549.99,549.895,,,,
186.572,182.756,9.55503,320.014,549.875,549.899,,,,
186.989,183.173,9.56059,320.001,549.846,549.931,,,,
187.405,183.589,9.56167,319.999,549.83,549.919,,,,
187.822,184.006,9.56418,320.001,549.913,549.948,,,,
188.239,184.423,9.56038,320.002,549.973,549.91,,,,
188.655,184.839,9.56097,320.005,549.903,549.791,,,,
189.072,185.256,9.56043,319.994,549.915,549.819,,,,
189.489,185.673,9.5684,320.003,549.84,549.884,,,,
189.905,186.089,9.56601,320,550.009,550.062,,,,
190.322,186.506,9.56199,319.999,549.891,549.806,,,,
190.739,186.923,9.56471,320.007,549.846,549.896,,,,
191.155,187.339,9.56168,320.005,549.881,549.897,,,,
191.572,187.756,9.56672,319.998,550.079,550.032,,,,
191.989,188.173,9.56221,320.01,549.998,549.887,,,,
192.405,188.589,9.56006,320.001,549.927,549.814,,,,
192.822,189.006,9.56412,319.998,549.853,549.891,,,,
193.239,189.423,9.56608,320,549.778,549.878,,,,
193.655,189.839,9.56455,320,549.858,549.919,,,,
194.072,190.256,9.56074,320.008,550.022,549.981,,,,
194.489,190.673,9.56025,320.006,549.937,549.831,,,,
194.905,191.089,9.56218,320.001,549.949,549.827,,,,
195.322,191.506,9.56364,319.998,549.872,549.884,,,,
195.739,191.923,9.55652,320.003,549.991,550.044,,,,
196.155,192.339,9.56616,320.004,549.945,549.996,,,,
196.572,192.756,9.56047,320.005,549.934,549.956,,,,
196.989,193.173,9.55965,319.994,549.967,549.917,,,,
197.405,193.589,9.55772,320.009,549.956,549.934,,,,
197.822,194.006,9.561,320.009,549.944,549.863,,,,
198.239,194.423,9.56026,319.996,549.902,549.886,,,,
198.655,194.839,9.56771,319.997,549.828,549.917,,,,
199.072,195.256,9.56314,320.007,549.884,549.933,,,,
199.489,195.673,9.56139,319.995,549.909,549.9,,,,
199.905,196.089,9.5597,320,549.94,549.834,,,,
200.322,196.506,9.55532,320.003,549.789,549.806,,,,
200.739,196.923,9.56431,319.998,549.87,549.916,,,,
201.155,197.339,9.56033,320.006,550.042,550.081,,,,
201.572,197.756,9.571,320.008,549.809,549.838,,,,
201.989,198.173,9.56311,320.005,549.938,549.934,,,,
202.405,198.589,9.56043,320,549.971,549.911,,,,
202.822,199.006,9.55739,320.005,550.008,549.934,,,,
203.239,199.423,9.56523,319.999,549.859,549.936,,,,
203.655,199.839,9.55942,320.008,549.74,549.828,,,,
204.002,200.186,9.5573,319.997,549.875,549.952,,,,
204.002,200.186,9.55498,318.145,549.882,549.952,,,,
204.002,200.186,9.55349,316.369,549.882,549.954,,,,
204.002,200.186,9.55247,314.549,549.879,549.954,,,,
204.002,200.186,9.5519,312.782,549.879,549.954,,,,
204.002,200.186,9.55161,310.903,549.879,549.963,,,,
204.002,200.186,9.55092,309.086,549.871,549.963,,,,
204.002,200.186,9.54959,307.251,549.871,549.963,,,,
204.003,200.186,9.54837,305.417,549.871,549.951,,,,
204.003,200.187,9.54664,303.576,549.871,549.951,,,,
204.003,200.187,9.54533,301.7,549.884,549.951,,,,
204.003,200.187,9.54429,299.743,549.884,549.951,,,,
204.003,200.187,9.54308,297.747,549.884,549.951,,,,
204.003,200.187,9.54204,295.734,549.876,549.951,,,,
204.003,200.187,9.54125,293.718,549.876,549.951,,,,
204.003,200.187,9.54004,291.706,549.876,549.948,,,,
204.003,200.187,9.53902,289.669,549.881,549.948,,,,
204.003,200.187,9.5379,287.615,549.881,549.948,,,,
204.003,200.187,9.53648,285.579,549.881,549.957,,,,
204.003,200.187,9.5352,283.551,549.882,549.957,,,,
204.004,200.187,9.53394,281.49,549.882,549.957,,,,
204.004,200.188,9.53319,279.472,549.882,549.957,,,,
204.004,200.188,9.53227,277.692,549.882,549.951,,,,
204.004,200.188,9.5316,275.913,549.894,549.951,,,,
204.004,200.188,9.53062,273.971,549.894,549.951,,,,
204.004,200.188,9.52938,272.2,549.894,549.951,,,,
204.004,200.188,9.52763,270.43,549.894,549.947,,,,
204.004,200.188,9.52607,268.642,549.887,549.947,,,,
204.004,200.188,9.52455,266.861,549.887,549.947,,,,
204.004,200.188,9.52262,265.101,549.887,549.947,,,,
204.004,200.188,9.52085,263.224,549.887,549.952,,,,
204.004,200.188,9.51868,261.276,549.889,549.952,,,,
204.004,200.188,9.51669,259.453,549.889,549.952,,,,
204.005,200.188,9.51515,257.634,549.889,549.952,,,,
204.005,200.188,9.51383,255.615,549.889,549.965,,,,
204.005,200.189,9.51206,253.749,549.89,549.965,,,,
204.005,200.189,9.50987,251.722,549.89,549.965,,,,
204.005,200.189,9.50774,249.778,549.89,549.977,,,,
204.005,200.189,9.50589,247.849,549.894,549.977,,,,
204.005,200.189,9.50359,245.795,549.894,549.977,,,,
204.005,200.189,9.5017,243.745,549.894,549.964,,,,
204.005,200.189,9.49958,241.72,549.894,549.964,,,,
204.005,200.189,9.49787,239.667,549.898,549.964,,,,
204.005,200.189,9.49648,237.612,549.898,549.964,,,,
204.005,200.189,9.4957,235.607,549.898,549.978,,,,
204.005,200.189,9.49487,233.583,549.902,549.978,,,,
204.006,200.189,9.49399,231.562,549.902,549.978,,,,
204.006,200.19,9.49315,229.541,549.902,549.974,,,,
204.006,200.19,9.49238,227.534,549.901,549.974,,,,
204.006,200.19,9.4911,225.484,549.901,549.974,,,,
204.006,200.19,9.48992,223.447,549.901,549.971,,,,
204.006,200.19,9.48906,221.437,549.901,549.971,,,,
204.006,200.19,9.48791,219.379,549.899,549.971,,,,
204.006,200.19,9.48683,217.334,549.899,549.971,,,,
204.006,200.19,9.48561,215.357,549.899,549.973,,,,
204.006,200.19,9.48423,213.313,549.894,549.973,,,,
204.006,200.19,9.48323,211.293,549.894,549.973,,,,
204.006,200.19,9.48233,209.234,549.894,549.965,,,,
204.007,200.19,9.48111,207.187,549.905,549.965,,,,
204.007,200.191,9.4797,205.151,549.905,549.965,,,,
204.007,200.191,9.47898,203.121,549.905,549.975,,,,
204.007,200.191,9.47849,201.115,549.895,549.975,,,,
204.007,200.191,9.47713,199.047,549.895,549.975,,,,
204.007,200.191,9.47528,197,549.895,549.975,,,,
204.007,200.191,9.47334,194.967,549.895,549.978,,,,
204.007,200.191,9.47154,192.955,549.901,549.978,,,,
204.007,200.191,9.46958,190.918,549.901,549.978,,,,
204.007,200.191,9.46777,188.875,549.901,549.981,,,,
204.007,200.191,9.46529,186.834,549.911,549.981,,,,
204.007,200.191,9.46372,184.82,549.911,549.981,,,,
204.008,200.191,9.46218,182.811,549.911,549.981,,,,
204.008,200.192,9.46085,180.766,549.911,549.994,,,,
204.008,200.192,9.4596,178.733,549.916,549.994,,,,
204.008,200.192,9.45846,176.697,549.916,549.994,,,,
204.008,200.192,9.45746,174.683,549.916,549.988,,,,
204.008,200.192,9.45658,172.696,549.931,549.988,,,,
204.008,200.192,9.45584,170.673,549.931,549.988,,,,
204.008,200.192,9.45566,170.269,549.931,549.988,,,,