File: Experiment/Experiment/Sample 3 Data/Sample3_240MPa_550C_200h.csv
Date/Clock time,45720.4,,,,
Tester,"Arik, Cameron",,,,
Specimen designation,316H-elg_240MPa_550C_03,,,,
Diameter,6.04267,mm,,,
Material,316H-elg,,,,
Load cell,100kN,,,,
Extensometer,Epsilon 3549 SN102121 GL25mm,,,,
"Gage length, standard travel",25,mm,,,
Test standard,ASTM E136,,,,
Machine data,ZwickRoell Kappa100 SS-CF,,,,
Time,Test time,Standard travel,Standard force,Temperature,Temperature 3
h,h,%,MPa,°C,°C
0.000617792,0.000308333,-1.29302,0.734553,23.3328,23.2381
0.0022039,0.000705556,0.00176331,1.78961,23.3478,23.2294
0.335537,0.334039,0.0716385,1.96955,78.5413,77.8101
0.668871,0.667372,0.215178,2.01257,189.379,189.034
1.0022,1.00071,0.407652,1.95491,292.778,293.729
1.33554,1.33404,0.606978,1.9489,393.32,393.34
1.66887,1.66737,0.811335,1.94795,493.044,489.628
2.0022,2.00071,0.961726,1.96795,550.722,547.792
2.33554,2.33404,0.981206,1.96675,552.68,550.653
2.66887,2.66737,0.982246,1.97363,548.122,547.13
3.0022,3.00071,0.984031,1.97488,547.136,546.656
3.33554,3.33404,0.985739,1.97142,547.897,548.293
3.66887,3.66737,0.995673,1.96563,549.43,549.617
3.99715,3.99565,0.990297,1.97472,549.789,550.464
4.00352,0.000125,0.00214094,2.82795,549.772,550.501
4.00359,0.000191667,0.00285512,4.40586,549.772,550.488
4.00366,0.000258333,0.00390892,5.96466,549.772,550.488
4.00372,0.000325,0.00521551,7.52087,549.772,550.488
4.00379,0.000391667,0.00656973,9.10385,549.772,550.488
4.00386,0.000458333,0.00798238,10.6771,549.766,550.486
4.00392,0.000525,0.00948421,12.2513,549.766,550.486
4.00399,0.000591667,0.0108404,13.8156,549.766,550.486
4.00406,0.000658333,0.012001,15.3463,549.766,550.486
4.00412,0.000725,0.0132383,16.8517,549.771,550.493
4.00419,0.000791667,0.0144026,18.3168,549.771,550.493
4.00426,0.000858333,0.0156483,19.7228,549.771,550.493
4.00432,0.000925,0.0168476,21.1548,549.771,550.493
4.00439,0.000991667,0.0179425,22.613,549.767,550.491
4.00446,0.00105833,0.0190963,24.0955,549.767,550.491
4.00452,0.001125,0.0202747,25.5797,549.767,550.491
4.00459,0.00119167,0.0215223,27.0711,549.767,550.491
4.00466,0.00125833,0.0226616,28.5736,549.769,550.491
4.00472,0.001325,0.0235059,30.1026,549.769,550.487
4.00479,0.00139167,0.0245739,31.6525,549.769,550.487
4.00486,0.00145833,0.0260915,33.1746,549.769,550.487
4.00492,0.001525,0.0274348,34.6807,549.759,550.487
4.00499,0.00159167,0.0284987,36.2287,549.759,550.488
4.00506,0.00165833,0.0297031,37.7718,549.759,550.488
4.00512,0.001725,0.0308419,39.3149,549.759,550.488
4.00519,0.00179167,0.0319427,40.8895,549.759,550.488
4.00526,0.00185833,0.0329756,42.4334,549.753,550.486
4.00532,0.001925,0.0341184,43.9642,549.753,550.486
4.00539,0.00199167,0.0353504,45.5115,549.753,550.486
4.00546,0.00205833,0.0363984,47.049,549.753,550.486
4.00552,0.002125,0.0376209,48.6094,549.762,550.496
4.00559,0.00219167,0.0388973,50.168,549.762,550.496
4.00566,0.00225833,0.0401807,51.6858,549.762,550.496
4.00572,0.002325,0.0413245,53.2017,549.762,550.496
4.00579,0.00239167,0.0424768,54.7407,549.771,550.491
4.00586,0.00245833,0.0436616,56.2872,549.771,550.491
4.00592,0.002525,0.0447497,57.8297,549.771,550.491
4.00599,0.00259167,0.0459087,59.3747,549.771,550.491
4.00606,0.00265833,0.0469527,60.9142,549.758,550.484
4.00612,0.002725,0.0479889,62.4129,549.758,550.484
4.00619,0.00279167,0.0491424,63.9364,549.758,550.484
4.00626,0.00285833,0.0504251,65.4712,549.758,550.484
4.00632,0.002925,0.0516057,66.998,549.744,550.484
4.00639,0.00299167,0.0528542,68.5317,549.744,550.476
4.00646,0.00305833,0.0539481,70.0617,549.744,550.476
4.00652,0.003125,0.055066,71.5721,549.744,550.476
4.00659,0.00319167,0.0561847,73.0724,549.741,550.476
4.00666,0.00325833,0.05724,74.5757,549.741,550.482
4.00672,0.003325,0.0583217,76.0937,549.741,550.482
4.00679,0.00339167,0.0594769,77.6097,549.741,550.482
4.00686,0.00345833,0.0605887,79.0976,549.745,550.482
4.00692,0.003525,0.0614284,80.5724,549.745,550.49
4.00699,0.00359167,0.0623172,82.0367,549.745,550.49
4.00706,0.00365833,0.0632526,83.5095,549.745,550.49
4.00712,0.003725,0.064302,84.974,549.747,550.49
4.00719,0.00379167,0.0651673,86.4376,549.747,550.48
4.00726,0.00385833,0.0659957,87.8844,549.747,550.48
4.00732,0.003925,0.067114,89.3002,549.747,550.48
4.0074,0.00399722,0.068115,90.8125,549.747,550.48
4.00747,0.00406944,0.0692019,92.3342,549.73,550.488
4.00755,0.00414722,0.070561,93.9462,549.73,550.488
4.00762,0.004225,0.0722063,95.5288,549.73,550.488
4.0077,0.00430278,0.0736315,97.052,549.73,550.488
4.00778,0.00438056,0.0749572,98.5677,549.732,550.481
4.00786,0.00445833,0.0766262,100.056,549.732,550.481
4.00793,0.00453611,0.0783926,101.5,549.732,550.481
4.00801,0.00461389,0.0800272,102.914,549.72,550.502
4.0081,0.00470278,0.0821308,104.445,549.72,550.502
4.00819,0.00479167,0.0840311,105.881,549.72,550.502
4.00829,0.00489167,0.086783,107.392,549.729,550.473
4.00839,0.00499444,0.089849,108.833,549.729,550.473
4.00851,0.00511389,0.0937865,110.299,549.729,550.473
4.00865,0.00525556,0.0987602,111.743,549.722,550.475
4.00882,0.005425,0.106019,113.176,549.721,550.475
4.00903,0.00562778,0.114659,114.596,549.721,550.484
4.00923,0.00583611,0.123444,116.041,549.724,550.49
4.00945,0.00605278,0.132527,117.462,549.713,550.474
4.00967,0.00627222,0.142464,118.894,549.708,550.472
4.0099,0.00649722,0.15242,120.318,549.708,550.472
4.01012,0.00672222,0.161571,121.764,549.696,550.476
4.01035,0.00695,0.17065,123.176,549.7,550.468
4.01059,0.00718889,0.180683,124.608,549.693,550.478
4.01082,0.00741944,0.190269,126.016,549.699,550.466
4.01107,0.00767222,0.200594,127.459,549.7,550.473
4.01132,0.00792222,0.211709,128.883,549.698,550.473
4.01158,0.00818056,0.222459,130.295,549.698,550.467
4.01185,0.00845278,0.233883,131.728,549.689,550.471
4.01212,0.00872222,0.246289,133.146,549.692,550.47
4.01241,0.00900833,0.258554,134.569,549.692,550.474
4.0127,0.00930278,0.271087,135.98,549.691,550.465
4.013,0.00960556,0.283976,137.395,549.689,550.476
4.01331,0.00991389,0.297145,138.81,549.682,550.486
4.01364,0.0102417,0.311926,140.23,549.682,550.478
4.01399,0.0105889,0.327362,141.649,549.674,550.48
4.01435,0.01095,0.343836,143.084,549.686,550.482
4.01472,0.0113194,0.359639,144.5,549.683,550.47
4.01511,0.0117083,0.377871,145.922,549.679,550.485
4.01551,0.0121139,0.395839,147.335,549.679,550.464
4.01593,0.0125306,0.414772,148.748,549.674,550.482
4.01636,0.0129639,0.436116,150.154,549.665,550.486
4.01683,0.0134278,0.457335,151.573,549.67,550.467
4.01731,0.0139139,0.481224,152.984,549.672,550.479
4.01782,0.014425,0.504393,154.401,549.677,550.484
4.01837,0.0149722,0.530415,155.81,549.684,550.482
4.01893,0.0155306,0.556576,157.216,549.682,550.498
4.01953,0.0161361,0.586542,158.627,549.683,550.485
4.02014,0.0167417,0.616066,160.027,549.686,550.49
4.02081,0.0174083,0.649698,161.439,549.699,550.471
4.02148,0.0180833,0.683288,162.845,549.714,550.446
4.02222,0.0188222,0.719993,164.256,549.729,550.427
4.02298,0.0195806,0.755571,165.663,549.727,550.419
4.02374,0.0203417,0.794262,167.073,549.752,550.41
4.02468,0.0212861,0.841719,168.475,549.764,550.431
4.0254,0.022,0.890165,169.882,549.77,550.418
4.02576,0.0223639,0.915784,171.296,549.782,550.434
4.02629,0.0228917,0.944239,171.284,549.786,550.439
4.02732,0.023925,0.979301,172.703,549.8,550.46
4.02762,0.024225,0.998532,174.121,549.809,550.467
4.02785,0.0244472,1.01416,172.635,549.816,550.473
4.02858,0.0251778,1.04502,174.05,549.825,550.485
4.02922,0.025825,1.06525,175.459,549.818,550.481
4.02992,0.0265167,1.11298,176.873,549.828,550.506
4.031,0.0275972,1.20379,178.279,549.838,550.525
4.03151,0.0281139,1.24417,179.697,549.855,550.537
4.03183,0.0284333,1.26394,178.249,549.848,550.539
4.03255,0.0291528,1.27059,178.968,549.869,550.555
4.03282,0.029425,1.27718,180.386,549.873,550.558
4.03316,0.0297639,1.28662,181.808,549.868,550.561
4.03362,0.030225,1.2999,181.758,549.881,550.579
4.03368,0.0302833,1.30341,180.276,549.881,550.579
4.03429,0.0308889,1.3277,180.972,549.876,550.591
4.03496,0.0315611,1.33854,182.392,549.889,550.595
4.03588,0.0324833,1.3969,183.815,549.895,550.607
4.03693,0.0335333,1.4843,185.221,549.91,550.63
4.03786,0.0344611,1.55997,186.629,549.919,550.654
4.03853,0.0351278,1.60016,188.041,549.919,550.661
4.0395,0.0360972,1.61311,188.774,549.943,550.662
4.03973,0.0363333,1.61451,190.202,549.935,550.67
4.03983,0.0364306,1.6168,188.649,549.935,550.67
4.0399,0.0365,1.61965,187.129,549.935,550.67
4.04063,0.0372278,1.64432,188.529,549.957,550.688
4.04131,0.0379083,1.65471,189.937,549.961,550.708
4.04271,0.0393083,1.75745,191.345,549.972,550.719
4.04365,0.04025,1.8341,192.749,549.974,550.736
4.04428,0.0408806,1.8836,194.156,549.988,550.747
4.04583,0.0424278,1.93933,195.568,550.001,550.759
4.04619,0.0427889,1.94179,196.985,550.006,550.769
4.04649,0.0430889,1.94492,196.986,550.006,550.764
4.04653,0.0431333,1.94711,195.357,550.006,550.764
4.04711,0.0437111,1.9715,195.314,550.016,550.769
4.048,0.0445972,1.98761,196.726,550.028,550.787
4.0483,0.0449056,1.99271,198.157,550.027,550.791
4.04883,0.0454361,2.03248,197.441,550.035,550.795
4.04975,0.0463556,2.10912,198.841,550.045,550.796
4.05051,0.0471139,2.1693,200.249,550.047,550.807
4.05198,0.0485778,2.27339,201.65,550.076,550.821
4.05261,0.0492111,2.2863,203.057,550.072,550.828
4.05335,0.04995,2.28884,204.476,550.086,550.834
4.05362,0.0502167,2.29365,203.591,550.092,550.831
4.05367,0.0502722,2.29733,202.116,550.092,550.831
4.05438,0.0509833,2.32988,202.807,550.104,550.841
4.05528,0.0518861,2.34393,204.209,550.113,550.85
4.05557,0.0521722,2.34658,205.646,550.109,550.863
4.05589,0.0524944,2.36049,205.623,550.116,550.865
4.05664,0.0532417,2.42036,205.586,550.125,550.865
4.05747,0.0540722,2.4892,206.992,550.134,550.871
4.05889,0.0554944,2.60515,208.39,550.142,550.889
4.05961,0.0562139,2.64696,209.792,550.153,550.891
4.06083,0.0574333,2.66323,211.197,550.155,550.894
4.06117,0.0577722,2.66517,212.618,550.165,550.891
4.06135,0.05795,2.67273,210.931,550.154,550.903
4.06142,0.0580194,2.67821,209.377,550.154,550.903
4.06233,0.0589278,2.71729,210.781,550.167,550.908
4.0631,0.0596972,2.72502,212.187,550.181,550.906
4.06349,0.0600917,2.72599,213.59,550.173,550.914
4.06385,0.0604556,2.73961,213.543,550.172,550.923
4.06422,0.0608194,2.77247,212.799,550.174,550.921
4.06513,0.0617361,2.84821,214.209,550.174,550.941
4.06644,0.0630417,2.95753,215.61,550.172,550.948
4.06723,0.0638361,3.01797,217.013,550.177,550.958
4.06847,0.0650722,3.05826,218.415,550.174,550.956
4.06914,0.0657417,3.06174,219.82,550.173,550.965
4.06951,0.0661139,3.06778,220.529,550.171,550.961
4.06956,0.0661611,3.07297,218.976,550.171,550.961
4.06963,0.0662306,3.08003,217.463,550.171,550.961
4.07054,0.0671417,3.12533,218.863,550.172,550.96
4.07138,0.0679833,3.13698,220.269,550.169,550.946
4.07194,0.0685444,3.14012,221.686,550.177,550.957
4.0722,0.0688056,3.1425,223.119,550.175,550.955
4.07241,0.0690111,3.1532,222.363,550.175,550.955
4.07249,0.0690917,3.16335,220.884,550.174,550.954
4.07392,0.0705167,3.28318,222.286,550.169,550.947
4.07478,0.0713778,3.35541,223.692,550.166,550.946
4.07582,0.0724167,3.4389,225.094,550.166,550.961
4.07686,0.0734639,3.47545,226.499,550.165,550.963
4.07779,0.0743889,3.4792,227.908,550.159,550.951
4.07813,0.0747306,3.48111,229.334,550.156,550.961
4.07827,0.0748722,3.49145,227.66,550.163,550.961
4.07832,0.074925,3.49836,226.115,550.163,550.958
4.07907,0.0756694,3.54628,226.812,550.166,550.948
4.07996,0.0765639,3.57009,228.218,550.154,550.958
4.08067,0.0772667,3.57405,229.623,550.145,550.959
4.08105,0.0776556,3.57591,231.035,550.152,550.958
4.08143,0.0780361,3.58836,230.985,550.14,550.949
4.08151,0.0781083,3.59768,229.481,550.14,550.949
4.08248,0.0790778,3.6803,230.17,550.139,550.95
4.08339,0.0799917,3.75565,231.573,550.14,550.953
4.08449,0.0810917,3.84609,232.974,550.127,550.941
4.08554,0.0821389,3.90451,234.377,550.123,550.944
4.08671,0.0833083,3.91701,235.781,550.128,550.937
4.08725,0.0838472,3.92061,237.202,550.136,550.928
4.0875,0.0841,3.92905,237.122,550.129,550.931
4.08754,0.0841444,3.93665,235.405,550.129,550.931
4.08801,0.0846111,3.9756,234.603,550.118,550.925
4.08893,0.0855278,4.02323,235.999,550.127,550.931
4.08961,0.0862111,4.03391,237.408,550.121,550.933
4.09045,0.0870556,4.03888,238.817,550.119,550.923
4.09088,0.0874833,4.0407,239.481,550.123,550.929
4.0909,0.0875,4.04273,240.046,550.123,550.929
4.09091,0.0875111,4.04111,234.281,550.123,550.929
4.09093,0.0875306,4.13851,236.848,550.123,550.929
4.09094,0.0875417,4.22027,239.133,550.123,550.929
4.09098,0.0875861,4.29711,239.24,550.123,550.929
4.091,0.0876056,4.30962,238.582,550.123,550.929
4.09104,0.0876417,4.32284,239.429,550.11,550.929
4.10796,0.104561,4.37737,239.998,550.021,550.796
4.17463,0.171228,4.38626,240.002,549.724,550.552
4.24129,0.237894,4.38932,239.999,549.505,550.323
4.30796,0.304561,4.39976,240.005,549.464,550.242
4.37463,0.371228,4.39612,240.011,549.638,550.387
4.44129,0.437894,4.38507,240.003,549.666,550.412
4.50796,0.504561,4.38271,239.987,549.505,550.22
4.57463,0.571228,4.38057,240.001,549.549,550.237
4.64129,0.637894,4.38658,239.996,549.548,550.166
4.70796,0.704561,4.38802,239.994,549.509,550.149
4.77463,0.771228,4.39007,239.991,549.462,550.14
4.84129,0.837894,4.39051,240.005,549.289,549.878
4.90796,0.904561,4.40145,239.996,549.738,550.393
4.97463,0.971228,4.39254,239.998,549.773,550.35
5.04129,1.03789,4.38946,240.002,549.722,550.188
5.24129,1.23789,4.39334,239.996,549.761,550.142
5.57463,1.57123,4.40921,240,549.663,549.948
5.90796,1.90456,4.39191,240.002,549.969,550.073
6.24129,2.23789,4.39953,240.007,549.909,549.893
6.57463,2.57123,4.40068,239.994,550.184,550.112
6.90796,2.90456,4.40735,239.989,550.008,549.924
7.24129,3.23789,4.39811,239.993,550.055,549.905
7.57463,3.57123,4.41048,240.003,549.736,549.643
7.90796,3.90456,4.4052,240.003,550.06,549.897
8.24129,4.23789,4.40643,239.998,550.322,550.202
8.57463,4.57123,4.41547,240,549.744,549.712
8.90796,4.90456,4.40878,240.002,549.851,549.746
9.24129,5.23789,4.40681,239.997,550.093,550.042
9.57463,5.57123,4.41804,239.997,549.663,549.674
9.90796,5.90456,4.40759,239.999,550.114,550.044
10.2413,6.23789,4.41117,239.999,550.164,550.17
10.5746,6.57123,4.41944,239.999,550.049,550.138
10.908,6.90456,4.41875,240.002,549.778,549.83
11.2413,7.23789,4.40781,239.993,549.882,549.874
11.5746,7.57123,4.4287,240.006,549.903,549.979
11.908,7.90456,4.41616,240.004,549.818,549.854
12.2413,8.23789,4.41446,240.005,550.033,549.98
12.5746,8.57123,4.41873,240.003,550.242,550.219
12.908,8.90456,4.4254,240.008,550.039,550.055
13.2413,9.23789,4.42733,239.999,549.796,549.901
13.5746,9.57123,4.41575,240.005,549.931,549.87
13.908,9.90456,4.41988,239.994,550.115,550.116
14.2413,10.2379,4.42726,239.995,549.568,549.574
14.5746,10.5712,4.42274,239.992,549.994,549.929
14.908,10.9046,4.42097,240.003,550.045,550
15.2413,11.2379,4.42311,239.989,549.818,549.801
15.5746,11.5712,4.43411,240.003,549.815,549.843
15.908,11.9046,4.42803,240.003,549.991,549.949
16.2413,12.2379,4.42074,239.996,550.099,550.092
16.5746,12.5712,4.43366,240.006,549.797,549.858
16.908,12.9046,4.42993,239.99,549.738,549.803
17.2413,13.2379,4.42279,239.997,549.961,549.941
17.5746,13.5712,4.43262,239.995,549.929,549.958
17.908,13.9046,4.435,240.009,549.91,549.959
18.2413,14.2379,4.42892,239.999,549.936,549.865
18.5746,14.5712,4.42934,240.004,550.119,550.136
18.908,14.9046,4.43694,240.01,549.726,549.668
19.2413,15.2379,4.43246,239.998,550.041,549.975
19.5746,15.5712,4.42669,240.002,550.062,550.052
19.908,15.9046,4.43357,240.003,549.649,549.635
20.2413,16.2379,4.43303,239.997,549.91,549.851
20.5746,16.5712,4.43013,239.988,550.227,550.168
20.908,16.9046,4.43507,239.999,549.957,549.999
21.2413,17.2379,4.43918,239.996,549.887,549.888
21.5746,17.5712,4.43342,240.001,550.106,550.118
21.908,17.9046,4.4368,239.997,549.741,549.777
22.2413,18.2379,4.43262,239.995,549.894,549.829
22.5746,18.5712,4.43627,240.007,550.209,550.148
22.908,18.9046,4.43949,239.994,550.016,550.036
23.2413,19.2379,4.43639,240.006,550.005,549.949
23.5746,19.5712,4.43506,239.998,550.028,549.986
23.908,19.9046,4.43506,240.003,550.109,550.101
24.2413,20.2379,4.44352,240.004,549.868,549.845
24.5746,20.5712,4.44276,239.998,549.569,549.643
24.908,20.9046,4.43759,240.003,549.99,549.938
25.2413,21.2379,4.43659,239.994,549.986,549.978
25.5746,21.5712,4.43334,239.994,550.011,550.044
25.908,21.9046,4.43325,240.003,549.841,549.849
26.2413,22.2379,4.43743,239.996,549.853,549.952
26.5746,22.5712,4.43337,239.996,549.928,549.956
26.908,22.9046,4.44097,240.003,549.639,549.651
27.2413,23.2379,4.4354,239.998,549.967,549.921
27.5746,23.5712,4.43483,240.002,550.039,550.075
27.908,23.9046,4.4428,239.995,549.758,549.862
28.2413,24.2379,4.43828,240.006,549.978,549.989
28.5746,24.5712,4.43597,239.995,549.917,549.973
28.908,24.9046,4.43951,239.993,549.668,549.766
29.2413,25.2379,4.4376,240.003,549.896,549.965
29.5746,25.5712,4.43108,239.995,549.924,549.926
29.908,25.9046,4.43014,240.008,550.006,549.99
30.2413,26.2379,4.44692,239.992,549.967,550.023
30.5746,26.5712,4.43847,240.002,549.783,549.826
30.908,26.9046,4.43534,239.986,549.994,549.961
31.2413,27.2379,4.43574,239.998,550,549.979
31.5746,27.5712,4.43927,239.991,550.234,550.299
31.908,27.9046,4.44333,239.993,549.857,549.938
32.2413,28.2379,4.44482,240.006,549.779,549.768
32.5746,28.5712,4.44107,239.998,549.704,549.797
32.908,28.9046,4.44602,240.004,549.981,550.004
33.2413,29.2379,4.44182,239.998,549.943,550.006
33.5746,29.5712,4.44767,239.999,549.921,549.937
33.908,29.9046,4.43839,239.997,549.958,549.924
34.2413,30.2379,4.44234,240.01,549.859,549.869
34.5746,30.5712,4.44368,240.005,550.212,550.279
34.908,30.9046,4.44924,240.002,549.865,549.856
35.2413,31.2379,4.4518,240.005,549.59,549.479
35.5746,31.5712,4.44775,239.995,549.922,549.97
35.908,31.9046,4.44657,240,550.087,550.057
36.2413,32.2379,4.44425,240,550.058,550.041
36.5746,32.5712,4.44653,240.009,550.076,550.121
36.908,32.9046,4.45261,240.001,549.676,549.565
37.2413,33.2379,4.45825,240.002,549.668,549.739
37.5746,33.5712,4.44931,240.004,549.945,549.976
37.908,33.9046,4.44807,240.004,550.011,549.995
38.2413,34.2379,4.4471,239.998,550.049,550.046
38.5746,34.5712,4.45395,239.998,550.308,550.331
38.908,34.9046,4.45945,239.995,549.888,549.687
39.2413,35.2379,4.45419,240.004,549.776,549.845
39.5746,35.5712,4.44997,240.004,549.887,549.877
39.908,35.9046,4.44882,240.007,549.976,550.007
40.2413,36.2379,4.45798,240.014,549.911,549.89
40.5746,36.5712,4.46282,240.006,549.905,549.929
40.908,36.9046,4.45446,239.995,549.872,549.954
41.2413,37.2379,4.45222,239.993,549.997,549.987
41.5746,37.5712,4.45341,240,550.121,550.202
41.908,37.9046,4.45015,240.003,549.984,549.997
42.2413,38.2379,4.46221,240.008,549.693,549.539
42.5746,38.5712,4.45062,239.999,549.812,549.904
42.908,38.9046,4.45355,239.995,549.99,549.975
43.2413,39.2379,4.45325,240.004,550.055,550.055
43.5746,39.5712,4.46022,240.001,549.785,549.708
43.908,39.9046,4.46089,239.995,549.968,549.968
44.2413,40.2379,4.4593,240.001,549.824,549.796
44.5746,40.5712,4.45907,239.997,549.534,549.376
44.908,40.9046,4.45362,239.992,549.992,550.014
45.2413,41.2379,4.45141,240,549.923,549.999
45.5746,41.5712,4.45964,239.996,549.734,549.841
45.908,41.9046,4.45381,240.002,550.014,550.033
46.2413,42.2379,4.45438,240.009,550.095,550.159
46.5746,42.5712,4.4611,239.999,550.066,550.113
46.908,42.9046,4.45869,240.003,549.945,549.976
47.2413,43.2379,4.45592,240.005,549.985,550.02
47.5746,43.5712,4.45503,239.988,549.916,549.945
47.908,43.9046,4.45485,240.004,549.944,550.002
48.2413,44.2379,4.4548,240.005,549.857,549.915
48.5746,44.5712,4.45799,240.002,550.068,550.109
48.908,44.9046,4.45996,239.996,549.86,549.775
49.2413,45.2379,4.45626,240.003,549.981,549.947
49.5746,45.5712,4.458,239.997,549.98,549.975
49.908,45.9046,4.45498,239.993,550.133,550.151
50.2413,46.2379,4.45843,240.01,549.839,549.787
50.5746,46.5712,4.45703,240.004,549.585,549.55
50.908,46.9046,4.45486,240.002,550.052,550.052
51.2413,47.2379,4.45665,240,550,550.051
51.5746,47.5712,4.46156,239.996,549.799,549.694
51.908,47.9046,4.46582,240.002,549.726,549.669
52.2413,48.2379,4.46548,239.989,549.718,549.825
52.5746,48.5712,4.45414,240.008,549.985,550.014
52.908,48.9046,4.45619,240.01,549.959,549.993
53.2413,49.2379,4.46291,240.003,549.867,549.65
53.5746,49.5712,4.46036,240.004,549.624,549.692
53.908,49.9046,4.45947,240.003,549.826,549.897
54.2413,50.2379,4.45328,240.01,549.917,549.934
54.5746,50.5712,4.45281,240.004,549.996,550.003
54.908,50.9046,4.4584,239.99,550.24,550.304
55.2413,51.2379,4.45592,240.001,549.663,549.482
55.5746,51.5712,4.45738,240,549.918,549.991
55.908,51.9046,4.45529,240.003,549.981,550.004
56.2413,52.2379,4.45868,240.004,550.269,550.321
56.5746,52.5712,4.46159,239.985,549.848,549.72
56.908,52.9046,4.46424,240.006,549.832,549.997
57.2413,53.2379,4.45689,240.003,549.927,549.979
57.5746,53.5712,4.45535,240.003,549.986,550.026
57.908,53.9046,4.45905,240.012,550.177,550.274
58.2413,54.2379,4.46108,240.001,549.829,549.603
58.5746,54.5712,4.45834,240.001,549.899,549.931
58.908,54.9046,4.45485,239.995,549.848,549.879
59.2413,55.2379,4.45949,239.998,550.098,550.138
59.5746,55.5712,4.46813,239.998,549.705,549.667
59.908,55.9046,4.4577,240.001,549.984,550.012
60.2413,56.2379,4.45663,240.008,549.968,549.966
60.5746,56.5712,4.46013,240,550.23,550.293
60.908,56.9046,4.46286,240,549.648,549.788
61.2413,57.2379,4.45279,239.989,549.933,549.933
61.5746,57.5712,4.45735,239.998,549.914,549.918
61.908,57.9046,4.46368,239.993,549.942,549.807
62.2413,58.2379,4.46162,239.998,549.829,549.906
62.5746,58.5712,4.45585,239.994,550.018,550.002
62.908,58.9046,4.47066,239.992,549.999,549.837
63.2413,59.2379,4.46524,240.002,549.819,549.925
63.5746,59.5712,4.45941,239.997,549.992,550.009
63.908,59.9046,4.45654,239.995,549.951,549.987
64.2413,60.2379,4.46385,240.004,550.245,550.337
64.5746,60.5712,4.46462,239.99,549.682,549.658
64.908,60.9046,4.45812,240,549.869,549.876
65.2413,61.2379,4.45603,239.997,549.957,549.979
65.5746,61.5712,4.46531,240.002,549.891,549.713
65.908,61.9046,4.46416,240.005,549.896,550.013
66.2413,62.2379,4.45993,239.996,549.971,549.975
66.5746,62.5712,4.45887,239.996,549.93,549.966
66.908,62.9046,4.46151,239.995,549.588,549.453
67.2413,63.2379,4.46378,239.993,549.758,549.905
67.5746,63.5712,4.45883,239.999,549.857,549.87
67.908,63.9046,4.46,239.996,550.193,550.265
68.2413,64.2379,4.46527,239.998,549.773,549.593
68.5746,64.5712,4.45882,239.999,549.895,549.968
68.908,64.9046,4.45682,240.002,550.03,550.03
69.2413,65.2379,4.46183,239.99,550.285,550.35
69.5746,65.5712,4.46525,240.002,549.683,549.701
69.908,65.9046,4.46055,240.009,549.89,549.901
70.2413,66.2379,4.45926,240.005,549.832,549.911
70.5746,66.5712,4.46178,240.008,549.803,549.561
70.908,66.9046,4.4699,239.995,549.867,549.912
71.2413,67.2379,4.45972,240.001,549.958,550.012
71.5746,67.5712,4.46572,239.995,550.08,550.094
71.908,67.9046,4.4665,240.002,549.895,549.937
72.2413,68.2379,4.45932,240.004,549.904,549.957
72.5746,68.5712,4.46951,239.999,549.702,549.75
72.908,68.9046,4.45928,240.001,549.961,549.964
73.2413,69.2379,4.46385,240.001,550.295,550.335
73.5746,69.5712,4.4701,239.994,549.765,549.82
73.908,69.9046,4.4586,239.998,549.909,549.97
74.2413,70.2379,4.46264,239.999,549.944,549.918
74.5746,70.5712,4.4633,240.001,550.289,550.332
74.908,70.9046,4.4659,240.005,549.9,550.001
75.2413,71.2379,4.45973,240.005,549.908,549.896
75.5746,71.5712,4.46573,239.995,549.619,549.489
75.908,71.9046,4.46171,239.999,549.951,549.94
76.2413,72.2379,4.46566,239.99,549.888,549.994
76.5746,72.5712,4.45871,239.997,549.932,549.944
76.908,72.9046,4.46313,240.003,549.957,549.954
77.2413,73.2379,4.471,240.001,549.763,549.702
77.5746,73.5712,4.46005,240.002,549.944,549.926
77.908,73.9046,4.45977,240.007,549.908,549.86
78.2413,74.2379,4.46015,239.997,549.869,549.964
78.5746,74.5712,4.45797,240.006,549.953,549.964
78.908,74.9046,4.46214,240,550.135,550.145
79.2413,75.2379,4.46894,240,549.823,549.91
79.5746,75.5712,4.45777,240.012,550.077,550.046
79.908,75.9046,4.46188,239.996,550.16,550.203
80.2413,76.2379,4.46985,239.999,549.972,549.96
80.5746,76.5712,4.4623,240.001,549.794,549.881
80.908,76.9046,4.45543,239.997,549.94,550.007
81.2413,77.2379,4.46394,240.001,549.949,549.868
81.5746,77.5712,4.46691,240,549.878,549.981
81.908,77.9046,4.45804,239.997,550.012,550.035
82.2413,78.2379,4.46208,239.998,550.308,550.394
82.5746,78.5712,4.46168,239.998,549.903,549.562
82.908,78.9046,4.47009,239.999,549.843,549.983
83.2413,79.2379,4.46052,240.006,549.763,549.874
83.5746,79.5712,4.46088,240.007,549.963,550.025
83.908,79.9046,4.46369,239.999,550.032,550.056
84.2413,80.2379,4.46252,240.005,549.705,549.596
84.5746,80.5712,4.46566,239.996,549.631,549.393
84.908,80.9046,4.45924,239.996,549.969,549.99
85.2413,81.2379,4.46154,240.014,550.031,550.097
85.5746,81.5712,4.46138,240.007,549.741,549.546
85.908,81.9046,4.46204,240.002,549.707,549.663
86.2413,82.2379,4.46397,240.001,549.908,549.963
86.5746,82.5712,4.46105,239.999,550.045,550.072
86.908,82.9046,4.46374,240.004,550.123,550.221
87.2413,83.2379,4.46671,239.997,549.767,549.678
87.5746,83.5712,4.45852,240.002,549.845,549.893
87.908,83.9046,4.46119,240.004,549.853,549.947
88.2413,84.2379,4.46439,240.009,549.773,549.611
88.5746,84.5712,4.47456,240,549.677,549.748
88.908,84.9046,4.46703,239.998,549.873,549.93
89.2413,85.2379,4.46164,239.999,550.031,550.057
89.5746,85.5712,4.46484,239.998,550.222,550.282
89.908,85.9046,4.47153,239.995,549.897,549.814
90.2413,86.2379,4.46695,240.002,549.715,549.647
90.5746,86.5712,4.46977,239.999,549.878,549.989
90.908,86.9046,4.46425,240.002,550,549.995
91.2413,87.2379,4.46666,240.002,549.938,549.838
91.5746,87.5712,4.4712,240,549.734,549.68
91.908,87.9046,4.46746,240,549.884,549.949
92.2413,88.2379,4.46607,240.006,550.011,550.028
92.5746,88.5712,4.4658,240.004,549.919,550.013
92.908,88.9046,4.47228,239.999,549.824,549.742
93.2413,89.2379,4.46283,239.998,549.84,549.948
93.5746,89.5712,4.46518,239.997,549.967,549.977
93.908,89.9046,4.46548,240,549.931,550.015
94.2413,90.2379,4.47054,240.002,549.77,549.6
94.5746,90.5712,4.47396,240.004,549.847,549.934
94.908,90.9046,4.46851,239.998,549.993,550.01
95.2413,91.2379,4.46762,239.996,550.221,550.303
95.5746,91.5712,4.47328,239.998,549.891,549.676
95.908,91.9046,4.46819,239.992,549.71,549.66
96.2413,92.2379,4.47276,240.003,549.82,549.954
96.5746,92.5712,4.46652,240.006,549.99,550.049
96.908,92.9046,4.46867,240.007,550.093,550.182
97.2413,93.2379,4.47194,239.994,549.871,549.793
97.5746,93.5712,4.47665,240.003,549.726,549.747
97.908,93.9046,4.47098,240,550.007,550.038
98.2413,94.2379,4.46666,239.996,549.975,550.041
98.5746,94.5712,4.4693,239.996,549.909,549.972
98.908,94.9046,4.46888,239.998,549.84,549.668
99.2413,95.2379,4.48046,240.002,549.826,549.906
99.5746,95.5712,4.47159,240.002,549.896,549.968
99.908,95.9046,4.46826,239.996,549.981,550.014
100.241,96.2379,4.47032,239.996,550.067,550.153
100.575,96.5712,4.47884,239.994,549.937,549.842
100.908,96.9046,4.47491,240.01,549.747,549.621
101.241,97.2379,4.4673,240.003,549.841,549.921
101.575,97.5712,4.47155,240,549.921,549.979
101.908,97.9046,4.47318,239.99,550.023,549.958
102.241,98.2379,4.46989,240.006,549.647,549.496
102.575,98.5712,4.47727,240.007,549.697,549.666
102.908,98.9046,4.47194,240.013,549.788,549.874
103.241,99.2379,4.47093,239.999,549.973,550.006
103.575,99.5712,4.46993,240,550.145,550.23
103.908,99.9046,4.48316,239.997,549.957,549.856
104.241,100.238,4.47356,240.001,549.82,549.886
104.575,100.571,4.47405,240,549.971,550.015
104.908,100.905,4.47182,240.006,549.93,549.99
105.241,101.238,4.47192,240.002,550.046,550.134
105.575,101.571,4.4743,240.004,550.121,550.191
105.908,101.905,4.47535,239.99,549.997,549.988
106.241,102.238,4.47534,239.996,549.825,549.575
106.575,102.571,4.47802,239.999,549.85,549.969
106.908,102.905,4.47289,239.994,549.887,549.92
107.241,103.238,4.47074,240.008,549.896,549.956
107.575,103.571,4.47553,239.999,550.191,550.26
107.908,103.905,4.48117,239.995,550.051,549.92
108.241,104.238,4.48333,239.999,549.73,549.642
108.575,104.571,4.48531,240.003,549.822,549.917
108.908,104.905,4.47463,239.997,549.98,550.045
109.241,105.238,4.47307,239.999,549.922,550.014
109.575,105.571,4.47793,240.011,549.951,549.997
109.908,105.905,4.48254,239.998,549.521,549.279
110.241,106.238,4.47687,239.997,549.745,549.833
110.575,106.571,4.48112,240.004,549.992,549.996
110.908,106.905,4.47288,240.001,549.989,550.034
111.241,107.238,4.47636,239.985,550.192,550.295
111.575,107.571,4.48278,240.002,549.936,549.846
111.908,107.905,4.48012,240.002,549.913,549.808
112.241,108.238,4.47749,240,549.803,549.861
112.575,108.571,4.4788,240.006,549.755,549.828
112.908,108.905,4.47626,240.002,549.949,550.009
113.241,109.238,4.47581,240.005,549.851,549.896
113.575,109.571,4.47676,240.001,550.174,550.272
113.908,109.905,4.47887,239.997,549.96,549.798
114.241,110.238,4.48436,240.006,549.606,549.37
114.575,110.571,4.48374,240.013,549.763,549.878
114.908,110.905,4.47516,239.999,549.969,550.027
115.241,111.238,4.47785,239.997,549.99,550.059
115.575,111.571,4.48116,240.003,550.192,550.158
115.908,111.905,4.48583,240.001,549.966,549.774
116.241,112.238,4.48127,239.999,549.788,549.648
116.575,112.571,4.48,239.997,549.827,549.989
116.908,112.905,4.4799,240.016,549.788,549.94
117.241,113.238,4.47729,239.988,549.973,550.049
117.575,113.571,4.47935,240.002,549.99,550.097
117.908,113.905,4.48467,240.005,549.898,549.665
118.241,114.238,4.4866,239.996,549.844,549.625
118.575,114.571,4.47911,240.009,549.706,549.53
118.908,114.905,4.48213,239.994,549.725,549.699
119.241,115.238,4.48525,239.994,549.721,549.838
119.575,115.571,4.47841,239.993,549.89,549.986
119.908,115.905,4.47942,239.999,549.889,549.98
120.241,116.238,4.48037,240.001,550.045,550.142
120.575,116.571,4.4871,240.002,549.909,549.83
120.908,116.905,4.48552,239.996,549.934,549.871
121.241,117.238,4.48973,240.004,549.659,549.503
121.575,117.571,4.48427,240.006,549.767,549.798
121.908,117.905,4.47972,240.005,549.999,550.043
122.241,118.238,4.48065,239.992,549.922,549.993
122.575,118.571,4.48161,240.006,550.157,550.264
122.908,118.905,4.48647,240.002,549.925,549.85
123.241,119.238,4.48926,240.009,549.927,549.697
123.575,119.571,4.48574,240.003,550.012,549.84
123.908,119.905,4.48493,239.984,549.761,549.59
124.241,120.238,4.49441,239.996,549.699,549.442
124.575,120.571,4.49299,240.001,549.669,549.522
124.908,120.905,4.48554,239.998,549.824,549.938
125.241,121.238,4.48226,240.001,549.941,550.003
125.575,121.571,4.48129,239.999,549.879,549.993
125.908,121.905,4.48338,239.995,550.024,550.143
126.241,122.238,4.48482,240,549.944,549.939
126.575,122.571,4.49077,239.998,549.936,549.811
126.908,122.905,4.49306,239.998,550.086,549.92
127.241,123.238,4.48857,240.001,549.719,549.524
127.575,123.571,4.49148,239.997,549.703,549.52
127.908,123.905,4.48685,239.993,549.74,549.79
128.241,124.238,4.48102,239.997,549.971,550.05
128.575,124.571,4.48485,240.006,550.223,550.315
128.908,124.905,4.48593,240.007,550.198,550.233
129.241,125.238,4.48715,239.991,549.888,549.782
129.575,125.571,4.49188,240.008,549.705,549.453
129.908,125.905,4.48349,239.999,549.734,549.846
130.241,126.238,4.48535,239.995,549.849,549.942
130.575,126.571,4.48128,239.994,549.851,549.921
130.908,126.905,4.48433,239.996,550.024,550.077
131.241,127.238,4.48512,240.013,550.06,550.154
131.575,127.571,4.49323,239.993,549.895,549.721
131.908,127.905,4.48628,240.001,549.886,549.721
132.241,128.238,4.48873,239.999,549.745,549.554
132.575,128.571,4.48103,239.995,549.622,549.39
132.908,128.905,4.48556,239.993,549.945,549.998
133.241,129.238,4.48532,240.011,550.009,550.067
133.575,129.571,4.48597,240.011,550.135,550.228
133.908,129.905,4.48783,239.998,549.919,549.869
134.241,130.238,4.48593,240.005,549.682,549.392
134.575,130.571,4.49256,239.999,549.711,549.613
134.908,130.905,4.49414,240.001,549.814,549.891
135.241,131.238,4.48447,239.997,550.006,550.068
135.575,131.571,4.48566,240.004,549.954,550.022
135.908,131.905,4.48501,240.005,549.96,550.055
136.241,132.238,4.48589,240,549.941,550.05
136.575,132.571,4.49072,239.992,550.001,549.975
136.908,132.905,4.48924,239.993,549.813,549.614
137.241,133.238,4.49639,240.006,549.74,549.822
137.575,133.571,4.49099,239.998,549.884,549.984
137.908,133.905,4.48754,240.005,549.982,550.021
138.241,134.238,4.48749,240.001,549.938,550.011
138.575,134.571,4.48576,240.001,550.011,550.103
138.908,134.905,4.49361,240.003,549.931,549.811
139.241,135.238,4.48839,239.999,549.724,549.446
139.575,135.571,4.49131,240.001,549.739,549.669
139.908,135.905,4.48756,239.999,549.882,549.965
140.241,136.238,4.48504,240,549.936,549.982
140.575,136.571,4.48837,239.997,550.144,550.232
140.908,136.905,4.49429,239.997,549.891,549.703
141.241,137.238,4.49016,240.003,550.041,550.06
141.575,137.571,4.48959,239.997,549.709,549.762
141.908,137.905,4.48829,240.001,549.998,550.033
142.241,138.238,4.48803,240.002,549.964,550.046
142.575,138.571,4.48839,240.005,549.844,549.54
142.908,138.905,4.48992,239.997,549.792,549.88
143.241,139.238,4.48502,239.995,550.012,550.055
143.575,139.571,4.49165,239.995,550.193,550.163
143.908,139.905,4.49678,240,549.719,549.758
144.241,140.238,4.48938,239.998,549.883,549.9
144.575,140.571,4.49538,239.996,549.813,549.813
144.908,140.905,4.49288,240.009,549.898,549.909
145.241,141.238,4.4826,240.01,549.92,550.008
145.575,141.571,4.48185,240.009,550.157,550.175
145.908,141.905,4.48247,239.994,549.853,549.871
146.241,142.238,4.4878,239.998,549.868,549.779
146.575,142.571,4.4867,239.999,549.83,549.888
146.908,142.905,4.48349,240.008,549.944,549.99
147.241,143.238,4.48692,240.008,549.856,549.846
147.575,143.571,4.48131,239.996,549.914,549.982
147.908,143.905,4.48417,239.994,549.925,549.935
148.241,144.238,4.4861,239.998,550.098,550.166
148.575,144.571,4.48566,240.005,549.785,549.846
148.908,144.905,4.47669,240.009,550,550.058
149.241,145.238,4.48344,240.007,549.917,549.739
149.575,145.571,4.47984,239.991,549.915,549.982
149.908,145.905,4.47852,240.004,550.082,550.167
150.241,146.238,4.48061,239.996,549.892,549.934
150.575,146.571,4.48679,239.997,549.919,549.777
150.908,146.905,4.47898,239.99,549.877,549.927
151.241,147.238,4.48441,240.002,550.034,550.022
151.575,147.571,4.48002,240,549.878,549.904
151.908,147.905,4.47914,240.007,550.014,550.064
152.241,148.238,4.48781,240.001,549.959,549.78
152.575,148.571,4.48585,240.001,549.811,549.651
152.908,148.905,4.47956,240.004,549.65,549.669
153.241,149.238,4.47924,240.001,549.978,550.035
153.575,149.571,4.48,240.003,549.985,550.053
153.908,149.905,4.47945,240.004,550.18,550.291
154.241,150.238,4.48508,240,549.949,549.897
154.575,150.571,4.48339,239.992,549.659,549.566
154.908,150.905,4.48598,239.999,549.617,549.718
155.241,151.238,4.47846,240.003,549.976,549.995
155.575,151.571,4.48098,239.996,550.056,550.056
155.908,151.905,4.4846,239.997,550.05,550.127
156.241,152.238,4.48403,239.997,550.162,550.286
156.575,152.571,4.48589,240.003,549.946,549.875
156.908,152.905,4.48665,239.996,549.873,549.778
157.241,153.238,4.48664,240.001,549.593,549.366
157.575,153.571,4.48786,240.003,549.694,549.738
157.908,153.905,4.48378,240.003,549.965,549.996
158.241,154.238,4.48237,240.006,549.945,549.972
158.575,154.571,4.48495,240.014,549.97,550.035
158.908,154.905,4.48552,240,550.059,550.149
159.241,155.238,4.48998,240.002,550.007,549.97
159.575,155.571,4.48509,239.998,549.943,549.837
159.908,155.905,4.49082,240.001,549.877,549.844
160.241,156.238,4.48945,239.999,549.741,549.703
160.575,156.571,4.48864,240,549.781,549.876
160.908,156.905,4.48545,240,549.95,550.013
161.241,157.238,4.48521,240,549.88,549.953
161.575,157.571,4.48716,240.01,549.952,550.059
161.908,157.905,4.49028,239.992,550.148,550.299
162.241,158.238,4.48555,240.005,550.014,550.135
162.575,158.571,4.49496,239.994,549.852,549.61
162.908,158.905,4.49754,239.999,550.039,550.018
163.241,159.238,4.48809,239.997,549.655,549.581
163.575,159.571,4.49167,240.007,549.705,549.716
163.908,159.905,4.48883,240.005,549.974,550.019
164.241,160.238,4.49098,239.998,549.843,549.607
164.575,160.571,4.49405,240.002,549.841,549.899
164.908,160.905,4.49281,240.001,549.913,549.947
165.241,161.238,4.49334,239.999,550.199,550.176
165.575,161.571,4.49757,240,549.721,549.653
165.908,161.905,4.49156,240.001,549.992,550.018
166.241,162.238,4.49054,240.002,549.872,549.954
166.575,162.571,4.49532,240.009,549.829,549.943
166.908,162.905,4.49198,240.006,549.982,550.04
167.241,163.238,4.49336,239.994,549.61,549.554
167.575,163.571,4.4921,239.997,549.723,549.852
167.908,163.905,4.48963,239.999,549.903,549.961
168.241,164.238,4.49861,240.004,549.796,549.565
168.575,164.571,4.49664,239.996,549.704,549.821
168.908,164.905,4.49009,240.009,550.036,550.051
169.241,165.238,4.49225,239.992,550.002,549.998
169.575,165.571,4.49085,240.003,549.954,550.003
169.908,165.905,4.49349,239.996,550.187,550.259
170.241,166.238,4.49721,239.996,550.158,550.231
170.575,166.571,4.49617,240.004,550.176,550.254
170.908,166.905,4.49391,240.003,550.046,550.111
171.241,167.238,4.49444,239.996,550.061,550.088
171.575,167.571,4.49768,239.998,549.678,549.653
171.908,167.905,4.50003,240.006,549.527,549.358
172.241,168.238,4.50259,240.01,549.52,549.297
172.575,168.571,4.50076,239.999,549.84,549.769
172.908,168.905,4.50283,239.991,549.712,549.801
173.241,169.238,4.49887,240.008,549.563,549.541
173.575,169.571,4.49967,239.993,549.921,549.959
173.908,169.905,4.50756,240.004,549.753,549.87
174.241,170.238,4.49771,239.998,549.962,549.966
174.575,170.571,4.51135,240.001,549.699,549.691
174.908,170.905,4.50654,240.009,549.705,549.742
175.241,171.238,4.49933,239.994,549.962,549.939
175.575,171.571,4.49684,240.005,550.068,550.069
175.908,171.905,4.49606,240,549.991,550.018
176.241,172.238,4.49806,240.006,550.045,550.106
176.575,172.571,4.49757,240.006,550.066,550.161
176.908,172.905,4.49843,240.002,550.168,550.259
177.241,173.238,4.49957,240.007,550.117,550.219
177.575,173.571,4.5023,239.997,550.221,550.27
177.908,173.905,4.5,239.993,550.027,550.125
178.241,174.238,4.50085,240.001,550.087,550.158
178.575,174.571,4.50381,239.995,550.088,550.151
178.908,174.905,4.50161,240.002,550.234,550.324
179.241,175.238,4.50077,239.999,550.232,550.335
179.575,175.571,4.50462,240.01,550.167,550.291
179.908,175.905,4.50122,239.993,550.032,550.11
180.241,176.238,4.50181,239.999,549.884,549.97
180.575,176.571,4.50242,240.01,549.884,549.934
180.908,176.905,4.50189,240.002,550.006,550.06
181.241,177.238,4.50264,239.99,550.034,550.064
181.575,177.571,4.50723,239.995,549.778,549.866
181.908,177.905,4.49945,240.002,549.621,549.581
182.241,178.238,4.50411,239.997,549.611,549.603
182.575,178.571,4.50713,240.002,549.946,549.999
182.908,178.905,4.50429,240.008,549.797,549.815
183.241,179.238,4.50251,239.994,549.579,549.499
183.575,179.571,4.51254,239.996,549.692,549.67
183.908,179.905,4.50333,239.998,549.684,549.694
184.241,180.238,4.50767,239.994,549.501,549.234
184.575,180.571,4.51236,239.998,549.797,549.821
184.908,180.905,4.51794,239.996,549.592,549.508
185.241,181.238,4.50553,240,549.725,549.759
185.575,181.571,4.51276,239.993,549.849,549.98
185.908,181.905,4.50574,239.999,549.873,549.961
186.241,182.238,4.5093,239.998,549.938,550.016
186.575,182.571,4.50493,239.996,549.823,549.893
186.908,182.905,4.50854,239.998,550.013,550.099
187.241,183.238,4.50915,239.998,550.228,550.316
187.575,183.571,4.51774,239.994,549.877,549.727
187.908,183.905,4.51237,240.009,549.974,549.8
188.241,184.238,4.51327,239.997,549.829,549.679
188.575,184.571,4.51304,240.021,549.627,549.442
188.908,184.905,4.51958,239.998,549.886,549.996
189.241,185.238,4.50992,240.001,549.917,549.988
189.575,185.571,4.51093,239.995,549.954,550.057
189.908,185.905,4.50989,239.995,549.974,550.086
190.241,186.238,4.51198,240.009,549.911,550.036
190.575,186.571,4.51232,239.998,550.006,550.174
190.908,186.905,4.514,239.995,550.032,550.17
191.241,187.238,4.51173,240.003,549.832,549.992
191.575,187.571,4.51494,240,549.851,550.002
191.908,187.905,4.51498,239.998,549.924,550.064
192.241,188.238,4.51549,240.011,549.961,550.07
192.575,188.571,4.5172,240.001,549.951,550.039
192.908,188.905,4.51494,239.998,549.942,550.082
193.241,189.238,4.51675,239.997,549.888,550.021
193.575,189.571,4.51302,239.999,549.888,549.971
193.908,189.905,4.51438,239.999,549.935,550.025
194.241,190.238,4.51472,240.003,549.931,550.038
194.575,190.571,4.51623,239.995,549.96,550.034
194.908,190.905,4.51682,239.999,549.984,550.072
195.241,191.238,4.5147,240.002,549.945,550.021
195.575,191.571,4.51696,239.997,550.158,550.31
195.908,191.905,4.51787,239.996,550.201,550.272
196.241,192.238,4.51288,240,549.897,549.961
196.575,192.571,4.51866,239.999,549.846,549.997
196.908,192.905,4.51202,239.994,549.967,550.015
197.241,193.238,4.51707,239.992,549.799,549.585
197.575,193.571,4.51654,240.005,549.829,549.917
197.908,193.905,4.51476,239.996,549.635,549.488
198.241,194.238,4.51478,239.996,549.632,549.56
198.575,194.571,4.51616,240,549.678,549.713
198.908,194.905,4.51736,240.007,549.778,549.492
199.241,195.238,4.52283,240.009,549.76,549.672
199.575,195.571,4.51559,240.001,549.932,549.854
199.908,195.905,4.51788,240.003,550.103,549.945
200.241,196.238,4.52475,239.998,550.163,550.124
200.575,196.571,4.51862,239.993,550.028,549.979
200.908,196.905,4.52436,239.986,549.625,549.471
201.241,197.238,4.51807,240.001,549.927,549.938
201.575,197.571,4.51982,240.005,549.775,549.561
201.908,197.905,4.5232,239.996,550.007,549.866
202.241,198.238,4.52576,239.997,550.011,549.942
202.575,198.571,4.517,239.993,549.892,549.699
202.908,198.905,4.51993,240.002,549.811,549.626
203.241,199.238,4.5203,240.002,549.911,549.741
203.575,199.571,4.52315,240,549.985,549.888
203.908,199.905,4.52099,239.986,550.1,550.028
204.09,200.086,4.51531,239.65,549.687,549.662
204.09,200.086,4.51418,238.089,549.687,549.662
204.09,200.086,4.51283,236.469,549.687,549.662
204.09,200.086,4.51217,234.853,549.686,549.662
204.09,200.086,4.51097,233.251,549.686,549.65
204.09,200.087,4.5108,231.621,549.686,549.65
204.09,200.087,4.50926,230.018,549.686,549.65
204.09,200.087,4.50848,228.362,549.686,549.65
204.09,200.087,4.5068,226.77,549.689,549.632
204.09,200.087,4.50592,225.367,549.689,549.632
204.09,200.087,4.50455,223.828,549.689,549.632
204.09,200.087,4.50348,222.173,549.689,549.632
204.09,200.087,4.50238,220.518,549.686,549.605
204.09,200.087,4.50122,218.862,549.686,549.605
204.09,200.087,4.50059,217.382,549.686,549.605
204.091,200.087,4.50013,215.901,549.686,549.605
204.091,200.087,4.49968,214.483,549.686,549.605
204.091,200.087,4.49936,213.038,549.674,549.59
204.091,200.087,4.49878,211.602,549.674,549.59
204.091,200.087,4.49862,210.152,549.674,549.59
204.091,200.087,4.49839,208.684,549.674,549.59
204.091,200.087,4.49825,207.215,549.674,549.59
204.091,200.088,4.49828,205.728,549.676,549.58
204.091,200.088,4.4981,204.229,549.676,549.58
204.091,200.088,4.49786,202.736,549.676,549.58
204.091,200.088,4.49701,201.249,549.676,549.58
204.091,200.088,4.49649,199.79,549.676,549.58
204.091,200.088,4.49574,198.306,549.674,549.571
204.091,200.088,4.49512,196.84,549.674,549.571
204.091,200.088,4.49485,195.36,549.674,549.571
204.091,200.088,4.49446,193.863,549.674,549.571
204.091,200.088,4.49376,192.384,549.674,549.571
204.091,200.088,4.49313,190.921,549.665,549.559
204.092,200.088,4.49194,189.464,549.665,549.559
204.092,200.088,4.49052,188.014,549.665,549.559
204.092,200.088,4.48891,186.554,549.665,549.559
204.092,200.088,4.48741,185.113,549.665,549.559
204.092,200.088,4.48593,183.651,549.674,549.558
204.092,200.088,4.48444,182.187,549.674,549.558
204.092,200.088,4.48298,180.729,549.674,549.558
204.092,200.089,4.48201,179.288,549.674,549.558
204.092,200.089,4.48122,177.854,549.674,549.558
204.092,200.089,4.48079,176.413,549.678,549.561
204.092,200.089,4.48017,174.959,549.678,549.561
204.092,200.089,4.47996,173.501,549.678,549.561
204.092,200.089,4.47931,172.059,549.678,549.561
204.092,200.089,4.47898,170.624,549.678,549.561
204.092,200.089,4.47867,169.126,549.675,549.555
204.092,200.089,4.47751,167.72,549.675,549.555
204.092,200.089,4.47724,166.235,549.675,549.555
204.092,200.089,4.47609,164.797,549.675,549.555
204.093,200.089,4.47446,163.371,549.675,549.555
204.093,200.089,4.47327,161.951,549.671,549.564
204.093,200.089,4.47195,160.527,549.671,549.564
204.093,200.089,4.47093,159.098,549.671,549.564
204.093,200.089,4.47038,157.499,549.671,549.564
204.093,200.089,4.46976,156.03,549.671,549.564
204.093,200.089,4.46908,154.613,549.667,549.561
204.093,200.09,4.46808,153.188,549.667,549.561
204.093,200.09,4.46694,151.779,549.667,549.561
204.093,200.09,4.46605,150.305,549.667,549.561
204.093,200.09,4.46483,148.761,549.67,549.561
204.093,200.09,4.46273,147.225,549.67,549.563
204.093,200.09,4.46153,145.687,549.67,549.563
204.093,200.09,4.46075,144.145,549.67,549.563
204.093,200.09,4.45898,142.736,549.67,549.563
204.093,200.09,4.45757,141.271,549.685,549.56
204.093,200.09,4.45657,139.628,549.685,549.56
204.094,200.09,4.45455,138.042,549.685,549.56
204.094,200.09,4.454,136.396,549.685,549.56
204.094,200.09,4.45184,134.752,549.678,549.558
204.094,200.09,4.45163,133.167,549.678,549.558
204.094,200.09,4.45041,131.572,549.678,549.558
204.094,200.09,4.44915,129.928,549.678,549.558
204.094,200.091,4.44796,128.292,549.678,549.558
204.094,200.091,4.44685,126.681,549.675,549.554
204.094,200.091,4.44532,125.067,549.675,549.554
204.094,200.091,4.44443,123.432,549.675,549.554
204.094,200.091,4.4433,121.814,549.675,549.554
204.094,200.091,4.44236,120.197,549.69,549.548
204.094,200.091,4.44127,118.572,549.69,549.548
204.094,200.091,4.44012,116.998,549.69,549.548
204.094,200.091,4.43925,115.393,549.69,549.548
204.095,200.091,4.43818,113.781,549.69,549.539
204.095,200.091,4.4372,112.158,549.69,549.539
204.095,200.091,4.43619,110.547,549.69,549.539
204.095,200.091,4.43535,108.952,549.69,549.539
204.095,200.091,4.43435,107.365,549.685,549.551
204.095,200.091,4.43379,105.793,549.685,549.551
204.095,200.092,4.43282,104.188,549.685,549.551
204.095,200.092,4.43256,102.584,549.685,549.551
204.095,200.092,4.43167,100.985,549.688,549.551
204.095,200.092,4.43102,99.3918,549.688,549.543
204.095,200.092,4.4303,97.8153,549.688,549.543
204.095,200.092,4.42956,96.2505,549.688,549.543
204.095,200.092,4.42885,94.6865,549.696,549.543
204.095,200.092,4.42821,93.1002,549.696,549.533
204.095,200.092,4.42681,91.5192,549.696,549.533
204.096,200.092,4.42604,89.9409,549.696,549.533
204.096,200.092,4.42493,88.4018,549.69,549.533
204.096,200.092,4.42436,86.856,549.69,549.534
204.096,200.092,4.42331,85.2979,549.69,549.534
204.096,200.092,4.42259,83.7405,549.69,549.534
204.096,200.092,4.42192,82.1801,549.69,549.534
204.096,200.093,4.42091,80.6265,549.699,549.538
204.096,200.093,4.42063,79.0963,549.699,549.538
204.096,200.093,4.41986,77.5703,549.699,549.538
204.096,200.093,4.41913,76.0403,549.699,549.538
204.096,200.093,4.41796,74.496,549.699,549.546
204.096,200.093,4.41735,72.9653,549.699,549.546
204.096,200.093,4.4162,71.4506,549.699,549.546
204.096,200.093,4.41634,69.9409,549.699,549.546
204.096,200.093,4.41471,68.4513,549.708,549.537
204.097,200.093,4.4148,66.94,549.708,549.537
204.097,200.093,4.41317,65.4297,549.708,549.537
204.097,200.093,4.41285,63.9238,549.708,549.537
204.097,200.093,4.41228,62.4375,549.709,549.543
204.097,200.093,4.41149,60.985,549.709,549.543
204.097,200.093,4.4116,59.526,549.709,549.543
204.097,200.094,4.41003,58.058,549.709,549.543
204.097,200.094,4.41038,56.5707,549.714,549.549
204.097,200.094,4.40887,55.1009,549.714,549.549
204.097,200.094,4.40845,53.6435,549.714,549.549
204.097,200.094,4.40817,52.1883,549.714,549.549
204.097,200.094,4.40777,50.7504,549.714,549.549
204.097,200.094,4.40721,49.3159,549.723,549.545
204.097,200.094,4.40686,47.8538,549.723,549.545
204.097,200.094,4.40528,46.4004,549.723,549.545
204.098,200.094,4.40351,44.9558,549.723,549.545
204.098,200.094,4.40208,43.5231,549.715,549.563
204.098,200.094,4.40024,42.0493,549.715,549.563
204.098,200.094,4.39854,40.574,549.715,549.563
204.098,200.094,4.39686,39.1269,549.715,549.563
204.098,200.094,4.39518,37.6733,549.731,549.563
204.098,200.095,4.39367,36.236,549.731,549.563
204.098,200.095,4.39246,34.7522,549.731,549.563
204.098,200.095,4.39116,33.3365,549.731,549.563
204.098,200.095,4.39009,31.8848,549.73,549.574
204.098,200.095,4.38865,30.4269,549.73,549.574
204.098,200.095,4.38754,28.9823,549.73,549.574
204.098,200.095,4.38616,27.5087,549.73,549.574
204.098,200.095,4.38472,26.0778,549.74,549.576
204.098,200.095,4.38404,24.5989,549.74,549.576
204.099,200.095,4.38283,23.1711,549.74,549.576
204.099,200.095,4.38205,21.7211,549.74,549.576
204.099,200.095,4.38075,20.2649,549.745,549.583
204.099,200.095,4.37989,18.8428,549.745,549.583
204.099,200.095,4.37866,17.3733,549.745,549.583
204.099,200.095,4.37696,15.8794,549.745,549.583
204.099,200.096,4.37548,14.3587,549.75,549.58
204.099,200.096,4.37446,12.9328,549.75,549.58
204.099,200.096,4.37307,11.4667,549.75,549.58
204.099,200.096,4.37151,9.96032,549.75,549.58
204.099,200.096,4.37026,8.39721,549.762,549.564
204.099,200.096,4.36966,6.81191,549.762,549.564
204.099,200.096,4.3689,5.25307,549.762,549.564
204.099,200.096,4.36769,3.71575,549.75,549.564
204.1,200.096,4.36609,2.26268,549.75,549.577
204.266,200.263,4.33032,1.26663,537.875,537.543
204.6,200.596,4.25701,1.28335,503.335,502.597
204.933,200.93,4.19526,1.26514,471.906,470.713
205.266,201.263,4.13995,1.26784,443.047,440.82
205.6,201.596,4.08441,1.27393,417.07,414.816
205.933,201.93,4.03967,1.27458,392.895,390.607
206.266,202.263,3.99792,1.25872,370.423,367.784
206.6,202.596,3.95016,1.27051,349.327,346.45
206.933,202.93,3.9085,1.25914,329.292,325.868
207.266,203.263,3.87926,1.26803,310.604,306.97
207.6,203.596,3.84218,1.26341,293.198,289.725
207.933,203.93,3.81511,1.2699,276.562,272.616
208.266,204.263,3.78525,1.25831,261.081,257.512
208.6,204.596,3.75552,1.26475,246.399,242.083
208.933,204.93,3.72682,1.25787,232.679,228.424
209.266,205.263,3.70708,1.27042,219.762,214.921
209.6,205.596,3.68051,1.27632,207.592,202.752
209.933,205.93,3.66248,1.26792,196.026,191.434
210.266,206.263,3.6424,1.26416,185.452,180.507
210.6,206.596,3.61951,1.25887,175.408,170.402
210.933,206.93,3.61087,1.26983,165.892,160.944
211.266,207.263,3.58959,1.26967,157.081,152.229
211.6,207.596,3.58234,1.26091,148.679,143.938
211.933,207.93,3.56272,1.26102,140.942,136.274
212.266,208.263,3.54878,1.26029,133.59,129.16
212.322,208.319,3.54717,0.489324,132.381,127.99
212.489,208.486,3.54895,1.26689,128.875,124.505
212.822,208.819,3.53048,1.26721,122.271,118.116
213.156,209.152,3.52293,1.26399,116.137,112.003
213.489,209.486,3.51655,1.26807,110.247,106.436
213.822,209.819,3.50155,1.25533,104.885,101.174
214.156,210.152,3.49696,1.27231,99.7805,96.2729
214.489,210.486,3.4846,1.26788,95.0005,91.6108
214.656,210.652,3.48834,1.2653,92.626,89.5738